Workbook

Sheet dados
A1: 3 | B1: 1 | C1: 1 | D1: 1 | E1: 1 | F1: 1 | G1: 1 | H1: 1 | I1: 1 | J1: 1 | K1: 1 | L1: 1 | M1: 1 | N1: 1 | O1: 1 | P1: 1 | Q1: 2 | R1: 1 | S1: 1 | T1: 1 | V1: 25 | W1: 9 | X1: 11 | Y1: 10 | Z1: 12 | AA1: 13 | AB1: 7 | AC1: 5 | AD1: 8 | AE1: 7 | AF1: 6 | AG1: 10 | AH1: 11 | AI1: 9 | AJ1: 11 | AK1: 5 | AL1: 28 | AM1: 9 | AN1: 6 | AO1: 11 | AR1: m | AS1: s2 | AT1: N
A2: 3 | B2: 3 | C2: 1 | D2: 1 | E2: 1 | F2: 3 | G2: 1 | H2: 1 | I2: 1 | J2: 1 | K2: 1 | L2: 1 | M2: 1 | N2: 1 | O2: 1 | P2: 1 | Q2: 2 | R2: 2 | S2: 1 | T2: 1 | V2: 32 | W2: 24 | X2: 10 | Y2: 6 | Z2: 12 | AA2: 30 | AB2: 13 | AC2: 13 | AD2: 18 | AE2: 11 | AF2: 5 | AG2: 10 | AH2: 10 | AI2: 11 | AJ2: 4 | AK2: 5 | AL2: 23 | AM2: 29 | AN2: 15 | AO2: 9 | AQ2: 1 | AR2: =AVERAGEIF($A$1:$T$20,AQ2,$V$1:$AO$20) -> 9.9825784 | AS2: {=(SUMSQ($V$1:$AO$20*IF($A$1:$T$20=AQ2,1,0))-COUNTIF($A$1:$T$20,AQ2)*AR2*AR2)/COUNTIF($A$1:$T$20,AQ2)} -> 9.1042261 | AT2: =COUNTIF($A$1:$T$20,AQ2) -> 287
A3: 3 | B3: 1 | C3: 1 | D3: 1 | E3: 1 | F3: 1 | G3: 3 | H3: 1 | I3: 1 | J3: 1 | K3: 1 | L3: 1 | M3: 1 | N3: 1 | O3: 1 | P3: 1 | Q3: 2 | R3: 2 | S3: 1 | T3: 1 | V3: 29 | W3: 10 | X3: 11 | Y3: 16 | Z3: 10 | AA3: 10 | AB3: 35 | AC3: 8 | AD3: 14 | AE3: 11 | AF3: 8 | AG3: 8 | AH3: 10 | AI3: 9 | AJ3: 9 | AK3: 11 | AL3: 13 | AM3: 20 | AN3: 6 | AO3: 13 | AQ3: 2 | AR3: =AVERAGEIF($A$1:$T$20,AQ3,$V$1:$AO$20) -> 21.098592 | AS3: {=(SUMSQ($V$1:$AO$20*IF($A$1:$T$20=AQ3,1,0))-COUNTIF($A$1:$T$20,AQ3)*AR3*AR3)/COUNTIF($A$1:$T$20,AQ3)} -> 20.962111 | AT3: =COUNTIF($A$1:$T$20,AQ3) -> 71
A4: 1 | B4: 3 | C4: 1 | D4: 1 | E4: 1 | F4: 1 | G4: 3 | H4: 1 | I4: 1 | J4: 1 | K4: 1 | L4: 1 | M4: 1 | N4: 1 | O4: 1 | P4: 1 | Q4: 1 | R4: 2 | S4: 2 | T4: 2 | V4: 7 | W4: 25 | X4: 8 | Y4: 4 | Z4: 11 | AA4: 10 | AB4: 18 | AC4: 13 | AD4: 9 | AE4: 5 | AF4: 14 | AG4: 9 | AH4: 8 | AI4: 10 | AJ4: 10 | AK4: 8 | AL4: 13 | AM4: 22 | AN4: 21 | AO4: 26 | AQ4: 3 | AR4: =AVERAGEIF($A$1:$T$20,AQ4,$V$1:$AO$20) -> 29.714286 | AS4: {=(SUMSQ($V$1:$AO$20*IF($A$1:$T$20=AQ4,1,0))-COUNTIF($A$1:$T$20,AQ4)*AR4*AR4)/COUNTIF($A$1:$T$20,AQ4)} -> 34.108844 | AT4: =COUNTIF($A$1:$T$20,AQ4) -> 42
A5: 1 | B5: 1 | C5: 3 | D5: 1 | E5: 1 | F5: 3 | G5: 3 | H5: 1 | I5: 1 | J5: 1 | K5: 1 | L5: 1 | M5: 1 | N5: 1 | O5: 1 | P5: 1 | Q5: 2 | R5: 2 | S5: 2 | T5: 1 | V5: 8 | W5: 7 | X5: 28 | Y5: 16 | Z5: 13 | AA5: 22 | AB5: 21 | AC5: 10 | AD5: 15 | AE5: 12 | AF5: 8 | AG5: 15 | AH5: 10 | AI5: 12 | AJ5: 8 | AK5: 9 | AL5: 15 | AM5: 24 | AN5: 20 | AO5: 10 | AQ5: Global | AR5: =AVERAGE(V1:AO20) -> 14.0275 | AS5: =_xlfn.VAR.P(V1:AO20) -> 60.286744 | AT5: =COUNT(V1:AO20) -> 400
A6: 1 | B6: 1 | C6: 1 | D6: 1 | E6: 1 | F6: 1 | G6: 1 | H6: 3 | I6: 1 | J6: 1 | K6: 1 | L6: 1 | M6: 1 | N6: 1 | O6: 1 | P6: 2 | Q6: 2 | R6: 2 | S6: 1 | T6: 1 | V6: 10 | W6: 7 | X6: 11 | Y6: 13 | Z6: 7 | AA6: 14 | AB6: 14 | AC6: 26 | AD6: 6 | AE6: 4 | AF6: 9 | AG6: 10 | AH6: 7 | AI6: 8 | AJ6: 11 | AK6: 26 | AL6: 20 | AM6: 30 | AN6: 9 | AO6: 11
A7: 2 | B7: 1 | C7: 1 | D7: 1 | E7: 1 | F7: 1 | G7: 1 | H7: 3 | I7: 3 | J7: 3 | K7: 1 | L7: 1 | M7: 2 | N7: 2 | O7: 2 | P7: 2 | Q7: 2 | R7: 1 | S7: 1 | T7: 1 | V7: 27 | W7: 11 | X7: 14 | Y7: 13 | Z7: 15 | AA7: 11 | AB7: 10 | AC7: 27 | AD7: 28 | AE7: 32 | AF7: 11 | AG7: 14 | AH7: 23 | AI7: 26 | AJ7: 13 | AK7: 19 | AL7: 20 | AM7: 9 | AN7: 10 | AO7: 11
A8: 1 | B8: 2 | C8: 2 | D8: 1 | E8: 2 | F8: 1 | G8: 3 | H8: 3 | I8: 3 | J8: 3 | K8: 2 | L8: 2 | M8: 2 | N8: 2 | O8: 2 | P8: 2 | Q8: 1 | R8: 1 | S8: 1 | T8: 1 | V8: 9 | W8: 18 | X8: 24 | Y8: 4 | Z8: 28 | AA8: 9 | AB8: 31 | AC8: 33 | AD8: 31 | AE8: 29 | AF8: 26 | AG8: 20 | AH8: 22 | AI8: 15 | AJ8: 14 | AK8: 22 | AL8: 8 | AM8: 8 | AN8: 16 | AO8: 11 | AQ8: #Estatística: Aplicação ao Sensoriamento Remoto - SER204, INPE, 2026
A9: 1 | B9: 1 | C9: 2 | D9: 2 | E9: 1 | F9: 1 | G9: 3 | H9: 3 | I9: 1 | J9: 2 | K9: 2 | L9: 2 | M9: 2 | N9: 1 | O9: 1 | P9: 1 | Q9: 1 | R9: 1 | S9: 1 | T9: 1 | V9: 10 | W9: 8 | X9: 26 | Y9: 22 | Z9: 8 | AA9: 8 | AB9: 24 | AC9: 36 | AD9: 7 | AE9: 17 | AF9: 18 | AG9: 24 | AH9: 14 | AI9: 7 | AJ9: 9 | AK9: 15 | AL9: 14 | AM9: 9 | AN9: 13 | AO9: 9 | AQ9: #https://cdrenno.github.io/Estatistica/
A10: 1 | B10: 1 | C10: 1 | D10: 2 | E10: 1 | F10: 1 | G10: 1 | H10: 1 | I10: 1 | J10: 2 | K10: 2 | L10: 2 | M10: 1 | N10: 1 | O10: 1 | P10: 1 | Q10: 1 | R10: 1 | S10: 1 | T10: 1 | V10: 8 | W10: 12 | X10: 10 | Y10: 22 | Z10: 19 | AA10: 14 | AB10: 6 | AC10: 12 | AD10: 6 | AE10: 14 | AF10: 26 | AG10: 19 | AH10: 15 | AI10: 13 | AJ10: 11 | AK10: 15 | AL10: 16 | AM10: 9 | AN10: 10 | AO10: 13
A11: 1 | B11: 1 | C11: 1 | D11: 2 | E11: 1 | F11: 1 | G11: 1 | H11: 1 | I11: 1 | J11: 2 | K11: 2 | L11: 2 | M11: 2 | N11: 1 | O11: 1 | P11: 1 | Q11: 1 | R11: 1 | S11: 1 | T11: 2 | V11: 7 | W11: 9 | X11: 16 | Y11: 21 | Z11: 8 | AA11: 10 | AB11: 4 | AC11: 8 | AD11: 11 | AE11: 19 | AF11: 17 | AG11: 19 | AH11: 18 | AI11: 14 | AJ11: 5 | AK11: 10 | AL11: 11 | AM11: 11 | AN11: 10 | AO11: 18
A12: 1 | B12: 1 | C12: 2 | D12: 1 | E12: 1 | F12: 1 | G12: 1 | H12: 1 | I12: 1 | J12: 2 | K12: 2 | L12: 1 | M12: 1 | N12: 1 | O12: 1 | P12: 1 | Q12: 1 | R12: 2 | S12: 2 | T12: 2 | V12: 11 | W12: 11 | X12: 22 | Y12: 11 | Z12: 13 | AA12: 14 | AB12: 8 | AC12: 10 | AD12: 9 | AE12: 21 | AF12: 16 | AG12: 13 | AH12: 5 | AI12: 6 | AJ12: 13 | AK12: 6 | AL12: 5 | AM12: 24 | AN12: 21 | AO12: 17
A13: 1 | B13: 2 | C13: 2 | D13: 1 | E13: 1 | F13: 1 | G13: 1 | H13: 1 | I13: 1 | J13: 1 | K13: 1 | L13: 1 | M13: 1 | N13: 1 | O13: 1 | P13: 1 | Q13: 1 | R13: 1 | S13: 2 | T13: 2 | V13: 11 | W13: 17 | X13: 18 | Y13: 10 | Z13: 13 | AA13: 8 | AB13: 14 | AC13: 14 | AD13: 11 | AE13: 11 | AF13: 13 | AG13: 11 | AH13: 5 | AI13: 8 | AJ13: 11 | AK13: 7 | AL13: 2 | AM13: 15 | AN13: 27 | AO13: 30
A14: 1 | B14: 2 | C14: 2 | D14: 1 | E14: 1 | F14: 1 | G14: 1 | H14: 1 | I14: 1 | J14: 1 | K14: 1 | L14: 1 | M14: 1 | N14: 1 | O14: 1 | P14: 1 | Q14: 1 | R14: 1 | S14: 1 | T14: 1 | V14: 7 | W14: 23 | X14: 22 | Y14: 13 | Z14: 13 | AA14: 11 | AB14: 10 | AC14: 6 | AD14: 12 | AE14: 7 | AF14: 5 | AG14: 9 | AH14: 13 | AI14: 9 | AJ14: 14 | AK14: 16 | AL14: 8 | AM14: 11 | AN14: 9 | AO14: 16
A15: 2 | B15: 2 | C15: 1 | D15: 1 | E15: 1 | F15: 1 | G15: 1 | H15: 1 | I15: 1 | J15: 1 | K15: 1 | L15: 3 | M15: 1 | N15: 1 | O15: 1 | P15: 1 | Q15: 1 | R15: 1 | S15: 1 | T15: 1 | V15: 20 | W15: 28 | X15: 12 | Y15: 12 | Z15: 6 | AA15: 9 | AB15: 6 | AC15: 12 | AD15: 15 | AE15: 10 | AF15: 14 | AG15: 39 | AH15: 12 | AI15: 8 | AJ15: 11 | AK15: 11 | AL15: 9 | AM15: 7 | AN15: 7 | AO15: 7
A16: 2 | B16: 2 | C16: 1 | D16: 1 | E16: 1 | F16: 1 | G16: 1 | H16: 1 | I16: 1 | J16: 1 | K16: 3 | L16: 3 | M16: 3 | N16: 1 | O16: 1 | P16: 1 | Q16: 1 | R16: 1 | S16: 1 | T16: 1 | V16: 19 | W16: 17 | X16: 5 | Y16: 10 | Z16: 11 | AA16: 5 | AB16: 13 | AC16: 10 | AD16: 11 | AE16: 12 | AF16: 44 | AG16: 33 | AH16: 35 | AI16: 8 | AJ16: 5 | AK16: 9 | AL16: 6 | AM16: 9 | AN16: 7 | AO16: 15
A17: 2 | B17: 2 | C17: 1 | D17: 1 | E17: 1 | F17: 1 | G17: 1 | H17: 1 | I17: 1 | J17: 1 | K17: 3 | L17: 3 | M17: 3 | N17: 1 | O17: 1 | P17: 1 | Q17: 1 | R17: 1 | S17: 1 | T17: 1 | V17: 23 | W17: 11 | X17: 14 | Y17: 13 | Z17: 9 | AA17: 8 | AB17: 7 | AC17: 8 | AD17: 11 | AE17: 12 | AF17: 35 | AG17: 35 | AH17: 23 | AI17: 8 | AJ17: 14 | AK17: 12 | AL17: 7 | AM17: 7 | AN17: 6 | AO17: 9
A18: 2 | B18: 2 | C18: 1 | D18: 1 | E18: 1 | F18: 1 | G18: 1 | H18: 1 | I18: 1 | J18: 1 | K18: 1 | L18: 1 | M18: 1 | N18: 1 | O18: 1 | P18: 1 | Q18: 1 | R18: 3 | S18: 3 | T18: 1 | V18: 16 | W18: 23 | X18: 8 | Y18: 12 | Z18: 8 | AA18: 9 | AB18: 13 | AC18: 13 | AD18: 15 | AE18: 11 | AF18: 10 | AG18: 9 | AH18: 14 | AI18: 10 | AJ18: 7 | AK18: 9 | AL18: 12 | AM18: 37 | AN18: 20 | AO18: 11
A19: 2 | B19: 2 | C19: 2 | D19: 3 | E19: 3 | F19: 1 | G19: 1 | H19: 1 | I19: 1 | J19: 1 | K19: 1 | L19: 1 | M19: 1 | N19: 1 | O19: 1 | P19: 1 | Q19: 3 | R19: 3 | S19: 3 | T19: 1 | V19: 22 | W19: 29 | X19: 14 | Y19: 28 | Z19: 29 | AA19: 12 | AB19: 4 | AC19: 8 | AD19: 13 | AE19: 7 | AF19: 10 | AG19: 14 | AH19: 5 | AI19: 11 | AJ19: 8 | AK19: 7 | AL19: 34 | AM19: 37 | AN19: 32 | AO19: 9
A20: 2 | B20: 2 | C20: 2 | D20: 3 | E20: 3 | F20: 3 | G20: 1 | H20: 1 | I20: 1 | J20: 1 | K20: 1 | L20: 1 | M20: 1 | N20: 1 | O20: 1 | P20: 1 | Q20: 3 | R20: 3 | S20: 3 | T20: 3 | V20: 19 | W20: 22 | X20: 29 | Y20: 33 | Z20: 25 | AA20: 27 | AB20: 13 | AC20: 9 | AD20: 9 | AE20: 7 | AF20: 8 | AG20: 4 | AH20: 15 | AI20: 8 | AJ20: 10 | AK20: 13 | AL20: 41 | AM20: 23 | AN20: 22 | AO20: 30
B22: l | C22: c | E22: v
A23: =RAND() -> 0.53155152 | B23: 1 | C23: 1 | D23: =INDIRECT(ADDRESS(B23,C23,1,0),0) -> 3 | E23: =INDIRECT(ADDRESS(B23,C23+21,1,0),0) -> 25
A24: =RAND() -> 0.62210183 | B24: 1 | C24: 2 | D24: =INDIRECT(ADDRESS(B24,C24,1,0),0) -> 1 | E24: =INDIRECT(ADDRESS(B24,C24+21,1,0),0) -> 9
A25: =RAND() -> 0.54761375 | B25: 1 | C25: 3 | D25: =INDIRECT(ADDRESS(B25,C25,1,0),0) -> 1 | E25: =INDIRECT(ADDRESS(B25,C25+21,1,0),0) -> 11
A26: =RAND() -> 0.66532628 | B26: 1 | C26: 4 | D26: =INDIRECT(ADDRESS(B26,C26,1,0),0) -> 1 | E26: =INDIRECT(ADDRESS(B26,C26+21,1,0),0) -> 10
A27: =RAND() -> 0.30645383 | B27: 1 | C27: 5 | D27: =INDIRECT(ADDRESS(B27,C27,1,0),0) -> 1 | E27: =INDIRECT(ADDRESS(B27,C27+21,1,0),0) -> 12
A28: =RAND() -> 0.82698037 | B28: 1 | C28: 6 | D28: =INDIRECT(ADDRESS(B28,C28,1,0),0) -> 1 | E28: =INDIRECT(ADDRESS(B28,C28+21,1,0),0) -> 13
A29: =RAND() -> 0.4109461 | B29: 1 | C29: 7 | D29: =INDIRECT(ADDRESS(B29,C29,1,0),0) -> 1 | E29: =INDIRECT(ADDRESS(B29,C29+21,1,0),0) -> 7
A30: =RAND() -> 0.90686605 | B30: 1 | C30: 8 | D30: =INDIRECT(ADDRESS(B30,C30,1,0),0) -> 1 | E30: =INDIRECT(ADDRESS(B30,C30+21,1,0),0) -> 5
A31: =RAND() -> 0.92565601 | B31: 1 | C31: 9 | D31: =INDIRECT(ADDRESS(B31,C31,1,0),0) -> 1 | E31: =INDIRECT(ADDRESS(B31,C31+21,1,0),0) -> 8
A32: =RAND() -> 0.38221917 | B32: 1 | C32: 10 | D32: =INDIRECT(ADDRESS(B32,C32,1,0),0) -> 1 | E32: =INDIRECT(ADDRESS(B32,C32+21,1,0),0) -> 7
A33: =RAND() -> 0.78896753 | B33: 1 | C33: 11 | D33: =INDIRECT(ADDRESS(B33,C33,1,0),0) -> 1 | E33: =INDIRECT(ADDRESS(B33,C33+21,1,0),0) -> 6
A34: =RAND() -> 0.22093936 | B34: 1 | C34: 12 | D34: =INDIRECT(ADDRESS(B34,C34,1,0),0) -> 1 | E34: =INDIRECT(ADDRESS(B34,C34+21,1,0),0) -> 10
... A42: =RAND() -> 0.54112746 | B42: 1 | C42: 20 | D42: =INDIRECT(ADDRESS(B42,C42,1,0),0) -> 1 | E42: =INDIRECT(ADDRESS(B42,C42+21,1,0),0) -> 11
A43: =RAND() -> 0.12497757 | B43: =B23+1 -> 2 | C43: =C23 -> 1 | D43: =INDIRECT(ADDRESS(B43,C43,1,0),0) -> 3 | E43: =INDIRECT(ADDRESS(B43,C43+21,1,0),0) -> 32
A44: =RAND() -> 0.28677628 | B44: =B24+1 -> 2 | C44: =C24 -> 2 | D44: =INDIRECT(ADDRESS(B44,C44,1,0),0) -> 3 | E44: =INDIRECT(ADDRESS(B44,C44+21,1,0),0) -> 24
A45: =RAND() -> 0.32678761 | B45: =B25+1 -> 2 | C45: =C25 -> 3 | D45: =INDIRECT(ADDRESS(B45,C45,1,0),0) -> 1 | E45: =INDIRECT(ADDRESS(B45,C45+21,1,0),0) -> 10
A46: =RAND() -> 0.61983126 | B46: =B26+1 -> 2 | C46: =C26 -> 4 | D46: =INDIRECT(ADDRESS(B46,C46,1,0),0) -> 1 | E46: =INDIRECT(ADDRESS(B46,C46+21,1,0),0) -> 6
A47: =RAND() -> 0.2557957 | B47: =B27+1 -> 2 | C47: =C27 -> 5 | D47: =INDIRECT(ADDRESS(B47,C47,1,0),0) -> 1 | E47: =INDIRECT(ADDRESS(B47,C47+21,1,0),0) -> 12
A48: =RAND() -> 0.8781909 | B48: =B28+1 -> 2 | C48: =C28 -> 6 | D48: =INDIRECT(ADDRESS(B48,C48,1,0),0) -> 3 | E48: =INDIRECT(ADDRESS(B48,C48+21,1,0),0) -> 30
...

Sheet simples
C1: Valor | F1: Xbarra | H1: m = | I1: =dados!AR5 -> 14.0275 | Q1: Boxplot | Z1: Outliers
A2: 1 | B2: =SMALL(dados!A$23:A$422,A2) -> 0.00051027568 | C2: =VLOOKUP(B2,dados!A$23:E$422,5,0) -> 9 | F2: #11 | G2: #20 | H2: #50 | I2: #100 | L2: =F2 -> #11 | M2: =G2 -> #20 | N2: =H2 -> #50 | O2: =I2 -> #100 | Q2: =F2 -> #11 | S2: =G2 -> #20 | U2: =H2 -> #50 | W2: =I2 -> #100 | Z2: =L2 -> #11 | AB2: =M2 -> #20 | AD2: =N2 -> #50 | AF2: =O2 -> #100
A3: 2 | B3: =SMALL(dados!A$23:A$422,A3) -> 0.002444935 | C3: =VLOOKUP(B3,dados!A$23:E$422,5,0) -> 9 | F3: =AVERAGE(C2:C12) -> 13.272727 | G3: =AVERAGE(C2:C21) -> 14.5 | H3: =AVERAGE(C2:C51) -> 14.52 | I3: =AVERAGE(C2:C101) -> 14.47 | K3: min | L3: {=MIN(IF(F4:F1003>(L4-1.5*(L6-L4)),F4:F1003,L4))} -> 8.4545455 | M3: {=MIN(IF(G4:G1003>(M4-1.5*(M6-M4)),G4:G1003,M4))} -> 9.75 | N3: {=MIN(IF(H4:H1003>(N4-1.5*(N6-N4)),H4:H1003,N4))} -> 11.26 | O3: {=MIN(IF(I4:I1003>(O4-1.5*(O6-O4)),I4:I1003,O4))} -> 12.36 | Q3: 0.75 | R3: =L7 -> 20 | S3: =Q3+1 -> 1.75 | T3: =M7 -> 18.45 | U3: =S3+1 -> 2.75 | V3: =N7 -> 16.86 | W3: =U3+1 -> 3.75 | X3: =O7 -> 15.75
A4: 3 | B4: =SMALL(dados!A$23:A$422,A4) -> 0.0040107505 | C4: =VLOOKUP(B4,dados!A$23:E$422,5,0) -> 6 | E4: 1 | F4: 11.909091 | G4: 12.65 | H4: 12.1 | I4: 14.55 | K4: 1q | L4: =_xlfn.QUARTILE.INC(F4:F1003,1) -> 12.363636 | M4: =_xlfn.QUARTILE.INC(G4:G1003,1) -> 12.8 | N4: =_xlfn.QUARTILE.INC(H4:H1003,1) -> 13.32 | O4: =_xlfn.QUARTILE.INC(I4:I1003,1) -> 13.58 | Q4: 1 | R4: =R3 -> 20 | S4: =Q4+1 -> 2 | T4: =T3 -> 18.45 | U4: =S4+1 -> 3 | V4: =V3 -> 16.86 | W4: =U4+1 -> 4 | X4: =X3 -> 15.75 | Z4: 1 | AA4: {=IF(OR(F4<L$3,F4>L$7),F4,#N/A)} -> #N/A | AB4: =Z4+1 -> 2 | AC4: {=IF(OR(G4<M$3,G4>M$7),G4,#N/A)} -> #N/A | AD4: =AB4+1 -> 3 | AE4: {=IF(OR(H4<N$3,H4>N$7),H4,#N/A)} -> #N/A | AF4: =AD4+1 -> 4 | AG4: {=IF(OR(I4<O$3,I4>O$7),I4,#N/A)} -> #N/A
A5: 4 | B5: =SMALL(dados!A$23:A$422,A5) -> 0.0082381268 | C5: =VLOOKUP(B5,dados!A$23:E$422,5,0) -> 15 | E5: 2 | F5: 13.090909 | G5: 15.75 | H5: 13.36 | I5: 13.78 | K5: med | L5: =MEDIAN(F4:F1003) -> 13.818182 | M5: =MEDIAN(G4:G1003) -> 13.925 | N5: =MEDIAN(H4:H1003) -> 14 | O5: =MEDIAN(I4:I1003) -> 14.04 | Q5: 1 | R5: =L6 -> 15.454545 | S5: =Q5+1 -> 2 | T5: =M6 -> 15.15 | U5: =S5+1 -> 3 | V5: =N6 -> 14.74 | W5: =U5+1 -> 4 | X5: =O6 -> 14.49 | Z5: 1 | AA5: {=IF(OR(F5<L$3,F5>L$7),F5,#N/A)} -> #N/A | AB5: =Z5+1 -> 2 | AC5: {=IF(OR(G5<M$3,G5>M$7),G5,#N/A)} -> #N/A | AD5: =AB5+1 -> 3 | AE5: {=IF(OR(H5<N$3,H5>N$7),H5,#N/A)} -> #N/A | AF5: =AD5+1 -> 4 | AG5: {=IF(OR(I5<O$3,I5>O$7),I5,#N/A)} -> #N/A
A6: 5 | B6: =SMALL(dados!A$23:A$422,A6) -> 0.0092508416 | C6: =VLOOKUP(B6,dados!A$23:E$422,5,0) -> 28 | E6: 3 | F6: 11.363636 | G6: 13.05 | H6: 13.66 | I6: 14.09 | K6: 3q | L6: =_xlfn.QUARTILE.INC(F4:F1003,3) -> 15.454545 | M6: =_xlfn.QUARTILE.INC(G4:G1003,3) -> 15.15 | N6: =_xlfn.QUARTILE.INC(H4:H1003,3) -> 14.74 | O6: =_xlfn.QUARTILE.INC(I4:I1003,3) -> 14.49 | Q6: 0.75 | R6: =R5 -> 15.454545 | S6: =Q6+1 -> 1.75 | T6: =T5 -> 15.15 | U6: =S6+1 -> 2.75 | V6: =V5 -> 14.74 | W6: =U6+1 -> 3.75 | X6: =X5 -> 14.49 | Z6: 1 | AA6: {=IF(OR(F6<L$3,F6>L$7),F6,#N/A)} -> #N/A | AB6: =Z6+1 -> 2 | AC6: {=IF(OR(G6<M$3,G6>M$7),G6,#N/A)} -> #N/A | AD6: =AB6+1 -> 3 | AE6: {=IF(OR(H6<N$3,H6>N$7),H6,#N/A)} -> #N/A | AF6: =AD6+1 -> 4 | AG6: {=IF(OR(I6<O$3,I6>O$7),I6,#N/A)} -> #N/A
A7: 6 | B7: =SMALL(dados!A$23:A$422,A7) -> 0.014387824 | C7: =VLOOKUP(B7,dados!A$23:E$422,5,0) -> 26 | E7: 4 | F7: 11.909091 | G7: 13 | H7: 12.74 | I7: 13.47 | K7: max | L7: {=MAX(IF(F4:F1003<(L6+1.5*(L6-L4)),F4:F1003,L6))} -> 20 | M7: {=MAX(IF(G4:G1003<(M6+1.5*(M6-M4)),G4:G1003,M6))} -> 18.45 | N7: {=MAX(IF(H4:H1003<(N6+1.5*(N6-N4)),H4:H1003,N6))} -> 16.86 | O7: {=MAX(IF(I4:I1003<(O6+1.5*(O6-O4)),I4:I1003,O6))} -> 15.75 | Q7: 0.75 | R7: =L5 -> 13.818182 | S7: =Q7+1 -> 1.75 | T7: =M5 -> 13.925 | U7: =S7+1 -> 2.75 | V7: =N5 -> 14 | W7: =U7+1 -> 3.75 | X7: =O5 -> 14.04 | Z7: 1 | AA7: {=IF(OR(F7<L$3,F7>L$7),F7,#N/A)} -> #N/A | AB7: =Z7+1 -> 2 | AC7: {=IF(OR(G7<M$3,G7>M$7),G7,#N/A)} -> #N/A | AD7: =AB7+1 -> 3 | AE7: {=IF(OR(H7<N$3,H7>N$7),H7,#N/A)} -> #N/A | AF7: =AD7+1 -> 4 | AG7: {=IF(OR(I7<O$3,I7>O$7),I7,#N/A)} -> #N/A
A8: 7 | B8: =SMALL(dados!A$23:A$422,A8) -> 0.015141544 | C8: =VLOOKUP(B8,dados!A$23:E$422,5,0) -> 7 | E8: 5 | F8: 13.545455 | G8: 12.8 | H8: 13.2 | I8: 12.86 | Q8: 1.25 | R8: =R7 -> 13.818182 | S8: =Q8+1 -> 2.25 | T8: =T7 -> 13.925 | U8: =S8+1 -> 3.25 | V8: =V7 -> 14 | W8: =U8+1 -> 4.25 | X8: =X7 -> 14.04 | Z8: 1 | AA8: {=IF(OR(F8<L$3,F8>L$7),F8,#N/A)} -> #N/A | AB8: =Z8+1 -> 2 | AC8: {=IF(OR(G8<M$3,G8>M$7),G8,#N/A)} -> #N/A | AD8: =AB8+1 -> 3 | AE8: {=IF(OR(H8<N$3,H8>N$7),H8,#N/A)} -> #N/A | AF8: =AD8+1 -> 4 | AG8: {=IF(OR(I8<O$3,I8>O$7),I8,#N/A)} -> #N/A
A9: 8 | B9: =SMALL(dados!A$23:A$422,A9) -> 0.016365066 | C9: =VLOOKUP(B9,dados!A$23:E$422,5,0) -> 11 | E9: 6 | F9: 15.636364 | G9: 15.1 | H9: 14.16 | I9: 13.2 | Q9: 1.25 | R9: =L4 -> 12.363636 | S9: =Q9+1 -> 2.25 | T9: =M4 -> 12.8 | U9: =S9+1 -> 3.25 | V9: =N4 -> 13.32 | W9: =U9+1 -> 4.25 | X9: =O4 -> 13.58 | Z9: 1 | AA9: {=IF(OR(F9<L$3,F9>L$7),F9,#N/A)} -> #N/A | AB9: =Z9+1 -> 2 | AC9: {=IF(OR(G9<M$3,G9>M$7),G9,#N/A)} -> #N/A | AD9: =AB9+1 -> 3 | AE9: {=IF(OR(H9<N$3,H9>N$7),H9,#N/A)} -> #N/A | AF9: =AD9+1 -> 4 | AG9: {=IF(OR(I9<O$3,I9>O$7),I9,#N/A)} -> #N/A
A10: 9 | B10: =SMALL(dados!A$23:A$422,A10) -> 0.024876855 | C10: =VLOOKUP(B10,dados!A$23:E$422,5,0) -> 5 | E10: 7 | F10: 10.090909 | G10: 12.2 | H10: 13.88 | I10: 14.89 | Q10: 1 | R10: =R9 -> 12.363636 | S10: =Q10+1 -> 2 | T10: =T9 -> 12.8 | U10: =S10+1 -> 3 | V10: =V9 -> 13.32 | W10: =U10+1 -> 4 | X10: =X9 -> 13.58 | Z10: 1 | AA10: {=IF(OR(F10<L$3,F10>L$7),F10,#N/A)} -> #N/A | AB10: =Z10+1 -> 2 | AC10: {=IF(OR(G10<M$3,G10>M$7),G10,#N/A)} -> #N/A | AD10: =AB10+1 -> 3 | AE10: {=IF(OR(H10<N$3,H10>N$7),H10,#N/A)} -> #N/A | AF10: =AD10+1 -> 4 | AG10: {=IF(OR(I10<O$3,I10>O$7),I10,#N/A)} -> #N/A
A11: 10 | B11: =SMALL(dados!A$23:A$422,A11) -> 0.028372084 | C11: =VLOOKUP(B11,dados!A$23:E$422,5,0) -> 20 | E11: 8 | F11: 12.636364 | G11: 11.9 | H11: 12.78 | I11: 12.71 | Q11: 1 | R11: =L3 -> 8.4545455 | S11: =Q11+1 -> 2 | T11: =M3 -> 9.75 | U11: =S11+1 -> 3 | V11: =N3 -> 11.26 | W11: =U11+1 -> 4 | X11: =O3 -> 12.36 | Z11: 1 | AA11: {=IF(OR(F11<L$3,F11>L$7),F11,#N/A)} -> #N/A | AB11: =Z11+1 -> 2 | AC11: {=IF(OR(G11<M$3,G11>M$7),G11,#N/A)} -> #N/A | AD11: =AB11+1 -> 3 | AE11: {=IF(OR(H11<N$3,H11>N$7),H11,#N/A)} -> #N/A | AF11: =AD11+1 -> 4 | AG11: {=IF(OR(I11<O$3,I11>O$7),I11,#N/A)} -> #N/A
A12: 11 | B12: =SMALL(dados!A$23:A$422,A12) -> 0.030016192 | C12: =VLOOKUP(B12,dados!A$23:E$422,5,0) -> 10 | E12: 9 | F12: 12.272727 | G12: 13.2 | H12: 13.3 | I12: 13.58 | Q12: 1.25 | R12: =R11 -> 8.4545455 | S12: =Q12+1 -> 2.25 | T12: =T11 -> 9.75 | U12: =S12+1 -> 3.25 | V12: =V11 -> 11.26 | W12: =U12+1 -> 4.25 | X12: =X11 -> 12.36 | Z12: 1 | AA12: {=IF(OR(F12<L$3,F12>L$7),F12,#N/A)} -> #N/A | AB12: =Z12+1 -> 2 | AC12: {=IF(OR(G12<M$3,G12>M$7),G12,#N/A)} -> #N/A | AD12: =AB12+1 -> 3 | AE12: {=IF(OR(H12<N$3,H12>N$7),H12,#N/A)} -> #N/A | AF12: =AD12+1 -> 4 | AG12: {=IF(OR(I12<O$3,I12>O$7),I12,#N/A)} -> #N/A
A13: 12 | B13: =SMALL(dados!A$23:A$422,A13) -> 0.030558105 | C13: =VLOOKUP(B13,dados!A$23:E$422,5,0) -> 9 | E13: 10 | F13: 13.454545 | G13: 13.75 | H13: 13.3 | I13: 14.42 | Q13: 0.75 | R13: =R11 -> 8.4545455 | S13: =Q13+1 -> 1.75 | T13: =T11 -> 9.75 | U13: =S13+1 -> 2.75 | V13: =V11 -> 11.26 | W13: =U13+1 -> 3.75 | X13: =X11 -> 12.36 | Z13: 1 | AA13: {=IF(OR(F13<L$3,F13>L$7),F13,#N/A)} -> #N/A | AB13: =Z13+1 -> 2 | AC13: {=IF(OR(G13<M$3,G13>M$7),G13,#N/A)} -> #N/A | AD13: =AB13+1 -> 3 | AE13: {=IF(OR(H13<N$3,H13>N$7),H13,#N/A)} -> #N/A | AF13: =AD13+1 -> 4 | AG13: {=IF(OR(I13<O$3,I13>O$7),I13,#N/A)} -> #N/A
A14: 13 | B14: =SMALL(dados!A$23:A$422,A14) -> 0.032498109 | C14: =VLOOKUP(B14,dados!A$23:E$422,5,0) -> 13 | E14: 11 | F14: 12.545455 | G14: 11.65 | H14: 13.72 | I14: 13.25 | Q14: 1 | R14: =R13 -> 8.4545455 | S14: =Q14+1 -> 2 | T14: =T13 -> 9.75 | U14: =S14+1 -> 3 | V14: =V13 -> 11.26 | W14: =U14+1 -> 4 | X14: =X13 -> 12.36 | Z14: 1 | AA14: {=IF(OR(F14<L$3,F14>L$7),F14,#N/A)} -> #N/A | AB14: =Z14+1 -> 2 | AC14: {=IF(OR(G14<M$3,G14>M$7),G14,#N/A)} -> #N/A | AD14: =AB14+1 -> 3 | AE14: {=IF(OR(H14<N$3,H14>N$7),H14,#N/A)} -> #N/A | AF14: =AD14+1 -> 4 | AG14: {=IF(OR(I14<O$3,I14>O$7),I14,#N/A)} -> #N/A
A15: 14 | B15: =SMALL(dados!A$23:A$422,A15) -> 0.033442967 | C15: =VLOOKUP(B15,dados!A$23:E$422,5,0) -> 36 | E15: 12 | F15: 14.727273 | G15: 13.95 | H15: 13.02 | I15: 13.82 | Q15: 1 | R15: =R9 -> 12.363636 | S15: =Q15+1 -> 2 | T15: =T9 -> 12.8 | U15: =S15+1 -> 3 | V15: =V9 -> 13.32 | W15: =U15+1 -> 4 | X15: =X9 -> 13.58 | Z15: 1 | AA15: {=IF(OR(F15<L$3,F15>L$7),F15,#N/A)} -> #N/A | AB15: =Z15+1 -> 2 | AC15: {=IF(OR(G15<M$3,G15>M$7),G15,#N/A)} -> #N/A | AD15: =AB15+1 -> 3 | AE15: {=IF(OR(H15<N$3,H15>N$7),H15,#N/A)} -> #N/A | AF15: =AD15+1 -> 4 | AG15: {=IF(OR(I15<O$3,I15>O$7),I15,#N/A)} -> #N/A
A16: 15 | B16: =SMALL(dados!A$23:A$422,A16) -> 0.040481216 | C16: =VLOOKUP(B16,dados!A$23:E$422,5,0) -> 14 | E16: 13 | F16: 17.181818 | G16: 14.45 | H16: 14.68 | I16: 14.37 | Q16: 0.75 | R16: =R15 -> 12.363636 | S16: =Q16+1 -> 1.75 | T16: =T15 -> 12.8 | U16: =S16+1 -> 2.75 | V16: =V15 -> 13.32 | W16: =U16+1 -> 3.75 | X16: =X15 -> 13.58 | Z16: 1 | AA16: {=IF(OR(F16<L$3,F16>L$7),F16,#N/A)} -> #N/A | AB16: =Z16+1 -> 2 | AC16: {=IF(OR(G16<M$3,G16>M$7),G16,#N/A)} -> #N/A | AD16: =AB16+1 -> 3 | AE16: {=IF(OR(H16<N$3,H16>N$7),H16,#N/A)} -> #N/A | AF16: =AD16+1 -> 4 | AG16: {=IF(OR(I16<O$3,I16>O$7),I16,#N/A)} -> #N/A
A17: 16 | B17: =SMALL(dados!A$23:A$422,A17) -> 0.043259559 | C17: =VLOOKUP(B17,dados!A$23:E$422,5,0) -> 21 | E17: 14 | F17: 12.090909 | G17: 12.65 | H17: 14.5 | I17: 15.22 | Q17: 0.75 | R17: =R7 -> 13.818182 | S17: =Q17+1 -> 1.75 | T17: =T7 -> 13.925 | U17: =S17+1 -> 2.75 | V17: =V7 -> 14 | W17: =U17+1 -> 3.75 | X17: =X7 -> 14.04 | Z17: 1 | AA17: {=IF(OR(F17<L$3,F17>L$7),F17,#N/A)} -> #N/A | AB17: =Z17+1 -> 2 | AC17: {=IF(OR(G17<M$3,G17>M$7),G17,#N/A)} -> #N/A | AD17: =AB17+1 -> 3 | AE17: {=IF(OR(H17<N$3,H17>N$7),H17,#N/A)} -> #N/A | AF17: =AD17+1 -> 4 | AG17: {=IF(OR(I17<O$3,I17>O$7),I17,#N/A)} -> #N/A
A18: 17 | B18: =SMALL(dados!A$23:A$422,A18) -> 0.043299396 | C18: =VLOOKUP(B18,dados!A$23:E$422,5,0) -> 20 | E18: 15 | F18: 13.636364 | G18: 15.55 | H18: 14.84 | I18: 14.39 | Q18: 1.25 | R18: =R17 -> 13.818182 | S18: =Q18+1 -> 2.25 | T18: =T17 -> 13.925 | U18: =S18+1 -> 3.25 | V18: =V17 -> 14 | W18: =U18+1 -> 4.25 | X18: =X17 -> 14.04 | Z18: 1 | AA18: {=IF(OR(F18<L$3,F18>L$7),F18,#N/A)} -> #N/A | AB18: =Z18+1 -> 2 | AC18: {=IF(OR(G18<M$3,G18>M$7),G18,#N/A)} -> #N/A | AD18: =AB18+1 -> 3 | AE18: {=IF(OR(H18<N$3,H18>N$7),H18,#N/A)} -> #N/A | AF18: =AD18+1 -> 4 | AG18: {=IF(OR(I18<O$3,I18>O$7),I18,#N/A)} -> #N/A
A19: 18 | B19: =SMALL(dados!A$23:A$422,A19) -> 0.047114437 | C19: =VLOOKUP(B19,dados!A$23:E$422,5,0) -> 11 | E19: 16 | F19: 14.909091 | G19: 12.7 | H19: 12.6 | I19: 13.39 | Q19: 1.25 | R19: =R5 -> 15.454545 | S19: =Q19+1 -> 2.25 | T19: =T5 -> 15.15 | U19: =S19+1 -> 3.25 | V19: =V5 -> 14.74 | W19: =U19+1 -> 4.25 | X19: =X5 -> 14.49 | Z19: 1 | AA19: {=IF(OR(F19<L$3,F19>L$7),F19,#N/A)} -> #N/A | AB19: =Z19+1 -> 2 | AC19: {=IF(OR(G19<M$3,G19>M$7),G19,#N/A)} -> #N/A | AD19: =AB19+1 -> 3 | AE19: {=IF(OR(H19<N$3,H19>N$7),H19,#N/A)} -> #N/A | AF19: =AD19+1 -> 4 | AG19: {=IF(OR(I19<O$3,I19>O$7),I19,#N/A)} -> #N/A
A20: 19 | B20: =SMALL(dados!A$23:A$422,A20) -> 0.048803968 | C20: =VLOOKUP(B20,dados!A$23:E$422,5,0) -> 15 | E20: 17 | F20: 11.545455 | G20: 12.4 | H20: 13.76 | I20: 14.35 | Q20: 1 | R20: =R19 -> 15.454545 | S20: =Q20+1 -> 2 | T20: =T19 -> 15.15 | U20: =S20+1 -> 3 | V20: =V19 -> 14.74 | W20: =U20+1 -> 4 | X20: =X19 -> 14.49 | Z20: 1 | AA20: {=IF(OR(F20<L$3,F20>L$7),F20,#N/A)} -> #N/A | AB20: =Z20+1 -> 2 | AC20: {=IF(OR(G20<M$3,G20>M$7),G20,#N/A)} -> #N/A | AD20: =AB20+1 -> 3 | AE20: {=IF(OR(H20<N$3,H20>N$7),H20,#N/A)} -> #N/A | AF20: =AD20+1 -> 4 | AG20: {=IF(OR(I20<O$3,I20>O$7),I20,#N/A)} -> #N/A
A21: 20 | B21: =SMALL(dados!A$23:A$422,A21) -> 0.049208211 | C21: =VLOOKUP(B21,dados!A$23:E$422,5,0) -> 5 | E21: 18 | F21: 13.818182 | G21: 15.7 | H21: 14.46 | I21: 14.82 | Q21: 1 | R21: =R3 -> 20 | S21: =Q21+1 -> 2 | T21: =T3 -> 18.45 | U21: =S21+1 -> 3 | V21: =V3 -> 16.86 | W21: =U21+1 -> 4 | X21: =X3 -> 15.75 | Z21: 1 | AA21: {=IF(OR(F21<L$3,F21>L$7),F21,#N/A)} -> #N/A | AB21: =Z21+1 -> 2 | AC21: {=IF(OR(G21<M$3,G21>M$7),G21,#N/A)} -> #N/A | AD21: =AB21+1 -> 3 | AE21: {=IF(OR(H21<N$3,H21>N$7),H21,#N/A)} -> #N/A | AF21: =AD21+1 -> 4 | AG21: {=IF(OR(I21<O$3,I21>O$7),I21,#N/A)} -> #N/A
A22: 21 | B22: =SMALL(dados!A$23:A$422,A22) -> 0.056803862 | C22: =VLOOKUP(B22,dados!A$23:E$422,5,0) -> 17 | E22: 19 | F22: 15.818182 | G22: 18.1 | H22: 15.08 | I22: 14.56 | Q22: 1.25 | R22: =R3 -> 20 | S22: =Q22+1 -> 2.25 | T22: =T3 -> 18.45 | U22: =S22+1 -> 3.25 | V22: =V3 -> 16.86 | W22: =U22+1 -> 4.25 | X22: =X3 -> 15.75 | Z22: 1 | AA22: {=IF(OR(F22<L$3,F22>L$7),F22,#N/A)} -> #N/A | AB22: =Z22+1 -> 2 | AC22: {=IF(OR(G22<M$3,G22>M$7),G22,#N/A)} -> #N/A | AD22: =AB22+1 -> 3 | AE22: {=IF(OR(H22<N$3,H22>N$7),H22,#N/A)} -> #N/A | AF22: =AD22+1 -> 4 | AG22: {=IF(OR(I22<O$3,I22>O$7),I22,#N/A)} -> #N/A
A23: 22 | B23: =SMALL(dados!A$23:A$422,A23) -> 0.060972481 | C23: =VLOOKUP(B23,dados!A$23:E$422,5,0) -> 35 | E23: 20 | F23: 13.818182 | G23: 14.05 | H23: 14 | I23: 14.08 | Z23: 1 | AA23: {=IF(OR(F23<L$3,F23>L$7),F23,#N/A)} -> #N/A | AB23: =Z23+1 -> 2 | AC23: {=IF(OR(G23<M$3,G23>M$7),G23,#N/A)} -> #N/A | AD23: =AB23+1 -> 3 | AE23: {=IF(OR(H23<N$3,H23>N$7),H23,#N/A)} -> #N/A | AF23: =AD23+1 -> 4 | AG23: {=IF(OR(I23<O$3,I23>O$7),I23,#N/A)} -> #N/A
A24: 23 | B24: =SMALL(dados!A$23:A$422,A24) -> 0.066785324 | C24: =VLOOKUP(B24,dados!A$23:E$422,5,0) -> 14 | E24: 21 | F24: 15.545455 | G24: 17.25 | H24: 15.58 | I24: 14.68 | Z24: 1 | AA24: {=IF(OR(F24<L$3,F24>L$7),F24,#N/A)} -> #N/A | AB24: =Z24+1 -> 2 | AC24: {=IF(OR(G24<M$3,G24>M$7),G24,#N/A)} -> #N/A | AD24: =AB24+1 -> 3 | AE24: {=IF(OR(H24<N$3,H24>N$7),H24,#N/A)} -> #N/A | AF24: =AD24+1 -> 4 | AG24: {=IF(OR(I24<O$3,I24>O$7),I24,#N/A)} -> #N/A
A25: 24 | B25: =SMALL(dados!A$23:A$422,A25) -> 0.066839328 | C25: =VLOOKUP(B25,dados!A$23:E$422,5,0) -> 16 | E25: 22 | F25: 15.818182 | G25: 15.4 | H25: 15.22 | I25: 14.77 | Z25: 1 | AA25: {=IF(OR(F25<L$3,F25>L$7),F25,#N/A)} -> #N/A | AB25: =Z25+1 -> 2 | AC25: {=IF(OR(G25<M$3,G25>M$7),G25,#N/A)} -> #N/A | AD25: =AB25+1 -> 3 | AE25: {=IF(OR(H25<N$3,H25>N$7),H25,#N/A)} -> #N/A | AF25: =AD25+1 -> 4 | AG25: {=IF(OR(I25<O$3,I25>O$7),I25,#N/A)} -> #N/A
A26: 25 | B26: =SMALL(dados!A$23:A$422,A26) -> 0.067138792 | C26: =VLOOKUP(B26,dados!A$23:E$422,5,0) -> 13 | E26: 23 | F26: 12.363636 | G26: 13.75 | H26: 13.3 | I26: 13.6 | Z26: 1 | AA26: {=IF(OR(F26<L$3,F26>L$7),F26,#N/A)} -> #N/A | AB26: =Z26+1 -> 2 | AC26: {=IF(OR(G26<M$3,G26>M$7),G26,#N/A)} -> #N/A | AD26: =AB26+1 -> 3 | AE26: {=IF(OR(H26<N$3,H26>N$7),H26,#N/A)} -> #N/A | AF26: =AD26+1 -> 4 | AG26: {=IF(OR(I26<O$3,I26>O$7),I26,#N/A)} -> #N/A
A27: 26 | B27: =SMALL(dados!A$23:A$422,A27) -> 0.067823811 | C27: =VLOOKUP(B27,dados!A$23:E$422,5,0) -> 13 | E27: 24 | F27: 12.727273 | G27: 13.45 | H27: 13.08 | I27: 12.44 | Z27: 1 | AA27: {=IF(OR(F27<L$3,F27>L$7),F27,#N/A)} -> #N/A | AB27: =Z27+1 -> 2 | AC27: {=IF(OR(G27<M$3,G27>M$7),G27,#N/A)} -> #N/A | AD27: =AB27+1 -> 3 | AE27: {=IF(OR(H27<N$3,H27>N$7),H27,#N/A)} -> #N/A | AF27: =AD27+1 -> 4 | AG27: {=IF(OR(I27<O$3,I27>O$7),I27,#N/A)} -> #N/A
A28: 27 | B28: =SMALL(dados!A$23:A$422,A28) -> 0.06809029 | C28: =VLOOKUP(B28,dados!A$23:E$422,5,0) -> 14 | E28: 25 | F28: 10.272727 | G28: 12.05 | H28: 12.5 | I28: 13.24 | Z28: 1 | AA28: {=IF(OR(F28<L$3,F28>L$7),F28,#N/A)} -> #N/A | AB28: =Z28+1 -> 2 | AC28: {=IF(OR(G28<M$3,G28>M$7),G28,#N/A)} -> #N/A | AD28: =AB28+1 -> 3 | AE28: {=IF(OR(H28<N$3,H28>N$7),H28,#N/A)} -> #N/A | AF28: =AD28+1 -> 4 | AG28: {=IF(OR(I28<O$3,I28>O$7),I28,#N/A)} -> #N/A
A29: 28 | B29: =SMALL(dados!A$23:A$422,A29) -> 0.069020494 | C29: =VLOOKUP(B29,dados!A$23:E$422,5,0) -> 9 | E29: 26 | F29: 13.454545 | G29: 13.6 | H29: 13.7 | I29: 14.66 | Z29: 1 | AA29: {=IF(OR(F29<L$3,F29>L$7),F29,#N/A)} -> #N/A | AB29: =Z29+1 -> 2 | AC29: {=IF(OR(G29<M$3,G29>M$7),G29,#N/A)} -> #N/A | AD29: =AB29+1 -> 3 | AE29: {=IF(OR(H29<N$3,H29>N$7),H29,#N/A)} -> #N/A | AF29: =AD29+1 -> 4 | AG29: {=IF(OR(I29<O$3,I29>O$7),I29,#N/A)} -> #N/A
A30: 29 | B30: =SMALL(dados!A$23:A$422,A30) -> 0.071655917 | C30: =VLOOKUP(B30,dados!A$23:E$422,5,0) -> 8 | E30: 27 | F30: 15.272727 | G30: 15.55 | H30: 13.84 | I30: 14.09 | Z30: 1 | AA30: {=IF(OR(F30<L$3,F30>L$7),F30,#N/A)} -> #N/A | AB30: =Z30+1 -> 2 | AC30: {=IF(OR(G30<M$3,G30>M$7),G30,#N/A)} -> #N/A | AD30: =AB30+1 -> 3 | AE30: {=IF(OR(H30<N$3,H30>N$7),H30,#N/A)} -> #N/A | AF30: =AD30+1 -> 4 | AG30: {=IF(OR(I30<O$3,I30>O$7),I30,#N/A)} -> #N/A
A31: 30 | B31: =SMALL(dados!A$23:A$422,A31) -> 0.072901778 | C31: =VLOOKUP(B31,dados!A$23:E$422,5,0) -> 13 | E31: 28 | F31: 11.181818 | G31: 12.2 | H31: 11.64 | I31: 12.91 | Z31: 1 | AA31: {=IF(OR(F31<L$3,F31>L$7),F31,#N/A)} -> #N/A | AB31: =Z31+1 -> 2 | AC31: {=IF(OR(G31<M$3,G31>M$7),G31,#N/A)} -> #N/A | AD31: =AB31+1 -> 3 | AE31: {=IF(OR(H31<N$3,H31>N$7),H31,#N/A)} -> #N/A | AF31: =AD31+1 -> 4 | AG31: {=IF(OR(I31<O$3,I31>O$7),I31,#N/A)} -> #N/A
A32: 31 | B32: =SMALL(dados!A$23:A$422,A32) -> 0.075074353 | C32: =VLOOKUP(B32,dados!A$23:E$422,5,0) -> 9 | E32: 29 | F32: 9.9090909 | G32: 11.5 | H32: 12.94 | I32: 12.91 | Z32: 1 | AA32: {=IF(OR(F32<L$3,F32>L$7),F32,#N/A)} -> #N/A | AB32: =Z32+1 -> 2 | AC32: {=IF(OR(G32<M$3,G32>M$7),G32,#N/A)} -> #N/A | AD32: =AB32+1 -> 3 | AE32: {=IF(OR(H32<N$3,H32>N$7),H32,#N/A)} -> #N/A | AF32: =AD32+1 -> 4 | AG32: {=IF(OR(I32<O$3,I32>O$7),I32,#N/A)} -> #N/A
A33: 32 | B33: =SMALL(dados!A$23:A$422,A33) -> 0.077291017 | C33: =VLOOKUP(B33,dados!A$23:E$422,5,0) -> 7 | E33: 30 | F33: 13.636364 | G33: 13.2 | H33: 13.46 | I33: 13.16 | Z33: 1 | AA33: {=IF(OR(F33<L$3,F33>L$7),F33,#N/A)} -> #N/A | AB33: =Z33+1 -> 2 | AC33: {=IF(OR(G33<M$3,G33>M$7),G33,#N/A)} -> #N/A | AD33: =AB33+1 -> 3 | AE33: {=IF(OR(H33<N$3,H33>N$7),H33,#N/A)} -> #N/A | AF33: =AD33+1 -> 4 | AG33: {=IF(OR(I33<O$3,I33>O$7),I33,#N/A)} -> #N/A
A34: 33 | B34: =SMALL(dados!A$23:A$422,A34) -> 0.078838512 | C34: =VLOOKUP(B34,dados!A$23:E$422,5,0) -> 22 | E34: 31 | F34: 13.909091 | G34: 14.3 | H34: 12.74 | I34: 13.35 | Z34: 1 | AA34: {=IF(OR(F34<L$3,F34>L$7),F34,#N/A)} -> #N/A | AB34: =Z34+1 -> 2 | AC34: {=IF(OR(G34<M$3,G34>M$7),G34,#N/A)} -> #N/A | AD34: =AB34+1 -> 3 | AE34: {=IF(OR(H34<N$3,H34>N$7),H34,#N/A)} -> #N/A | AF34: =AD34+1 -> 4 | AG34: {=IF(OR(I34<O$3,I34>O$7),I34,#N/A)} -> #N/A
... A201: 200 | B201: =SMALL(dados!A$23:A$422,A201) -> 0.51250793 | C201: =VLOOKUP(B201,dados!A$23:E$422,5,0) -> 8 | E201: 198 | F201: 17.909091 | G201: 17.5 | H201: 13.84 | I201: 14.42 | Z201: 1 | AA201: {=IF(OR(F201<L$3,F201>L$7),F201,#N/A)} -> #N/A | AB201: =Z201+1 -> 2 | AC201: {=IF(OR(G201<M$3,G201>M$7),G201,#N/A)} -> #N/A | AD201: =AB201+1 -> 3 | AE201: {=IF(OR(H201<N$3,H201>N$7),H201,#N/A)} -> #N/A | AF201: =AD201+1 -> 4 | AG201: {=IF(OR(I201<O$3,I201>O$7),I201,#N/A)} -> #N/A
A202: 201 | B202: =SMALL(dados!A$23:A$422,A202) -> 0.51297963 | E202: 199 | F202: 13.181818 | G202: 12.75 | H202: 13.32 | I202: 13.26 | Z202: 1 | AA202: {=IF(OR(F202<L$3,F202>L$7),F202,#N/A)} -> #N/A | AB202: =Z202+1 -> 2 | AC202: {=IF(OR(G202<M$3,G202>M$7),G202,#N/A)} -> #N/A | AD202: =AB202+1 -> 3 | AE202: {=IF(OR(H202<N$3,H202>N$7),H202,#N/A)} -> #N/A | AF202: =AD202+1 -> 4 | AG202: {=IF(OR(I202<O$3,I202>O$7),I202,#N/A)} -> #N/A
A203: 202 | B203: =SMALL(dados!A$23:A$422,A203) -> 0.51347887 | E203: 200 | F203: 15.454545 | G203: 14.85 | H203: 14.3 | I203: 13.63 | Z203: 1 | AA203: {=IF(OR(F203<L$3,F203>L$7),F203,#N/A)} -> #N/A | AB203: =Z203+1 -> 2 | AC203: {=IF(OR(G203<M$3,G203>M$7),G203,#N/A)} -> #N/A | AD203: =AB203+1 -> 3 | AE203: {=IF(OR(H203<N$3,H203>N$7),H203,#N/A)} -> #N/A | AF203: =AD203+1 -> 4 | AG203: {=IF(OR(I203<O$3,I203>O$7),I203,#N/A)} -> #N/A
A204: 203 | B204: =SMALL(dados!A$23:A$422,A204) -> 0.51480361 | E204: 201 | F204: 17.090909 | G204: 15.05 | H204: 14.98 | I204: 14.83 | Z204: 1 | AA204: {=IF(OR(F204<L$3,F204>L$7),F204,#N/A)} -> #N/A | AB204: =Z204+1 -> 2 | AC204: {=IF(OR(G204<M$3,G204>M$7),G204,#N/A)} -> #N/A | AD204: =AB204+1 -> 3 | AE204: {=IF(OR(H204<N$3,H204>N$7),H204,#N/A)} -> #N/A | AF204: =AD204+1 -> 4 | AG204: {=IF(OR(I204<O$3,I204>O$7),I204,#N/A)} -> #N/A
A205: 204 | B205: =SMALL(dados!A$23:A$422,A205) -> 0.51492721 | E205: 202 | F205: 11 | G205: 12.9 | H205: 12.66 | I205: 13.43 | Z205: 1 | AA205: {=IF(OR(F205<L$3,F205>L$7),F205,#N/A)} -> #N/A | AB205: =Z205+1 -> 2 | AC205: {=IF(OR(G205<M$3,G205>M$7),G205,#N/A)} -> #N/A | AD205: =AB205+1 -> 3 | AE205: {=IF(OR(H205<N$3,H205>N$7),H205,#N/A)} -> #N/A | AF205: =AD205+1 -> 4 | AG205: {=IF(OR(I205<O$3,I205>O$7),I205,#N/A)} -> #N/A
A206: 205 | B206: =SMALL(dados!A$23:A$422,A206) -> 0.51693943 | E206: 203 | F206: 16.636364 | G206: 15.5 | H206: 15.16 | I206: 14.09 | Z206: 1 | AA206: {=IF(OR(F206<L$3,F206>L$7),F206,#N/A)} -> #N/A | AB206: =Z206+1 -> 2 | AC206: {=IF(OR(G206<M$3,G206>M$7),G206,#N/A)} -> #N/A | AD206: =AB206+1 -> 3 | AE206: {=IF(OR(H206<N$3,H206>N$7),H206,#N/A)} -> #N/A | AF206: =AD206+1 -> 4 | AG206: {=IF(OR(I206<O$3,I206>O$7),I206,#N/A)} -> #N/A
...

Sheet estratificada
D1: Valor | E1: #1 | F1: #2 | G1: #3 | J1: N | M1: Xbarra | O1: m = | P1: =dados!AR5 -> 14.0275 | X1: Boxplot | AG1: Outliers | AP1: Xbarra1 | AR1: m = | AS1: =dados!AR2 -> 9.9825784 | AU1: Xbarra2 | AW1: m = | AX1: =dados!AR3 -> 21.098592 | AZ1: Xbarra3 | BB1: m = | BC1: =dados!AR4 -> 29.714286
A2: 1 | B2: =SMALL(dados!A$23:A$422,A2) -> 0.00051027568 | C2: =VLOOKUP(B2,dados!A$23:E$422,4,0) -> 1 | D2: =VLOOKUP(B2,dados!A$23:E$422,5,0) -> 9 | E2: =COUNTIF(C$2:C2,1) -> 1 | F2: =COUNTIF(C$2:C2,2) -> 0 | G2: =COUNTIF(C$2:C2,3) -> 0 | I2: 1 | J2: =COUNTIF(dados!$A$1:$T$20,I2) -> 287 | M2: #11 | N2: #20 | O2: #50 | P2: #100 | S2: =M2 -> #11 | T2: =N2 -> #20 | U2: =O2 -> #50 | V2: =P2 -> #100 | X2: =S2 -> #11 | Z2: =T2 -> #20 | AB2: =U2 -> #50 | AD2: =V2 -> #100 | AG2: =S2 -> #11 | AI2: =T2 -> #20 | AK2: =U2 -> #50 | AM2: =V2 -> #100 | AP2: #11 | AQ2: #20 | AR2: #50 | AS2: #100 | AU2: #11 | AV2: #20 | AW2: #50 | AX2: #100 | AZ2: #10 | BA2: #20 | BB2: #50 | BC2: #100
A3: 2 | B3: =SMALL(dados!A$23:A$422,A3) -> 0.002444935 | C3: =VLOOKUP(B3,dados!A$23:E$422,4,0) -> 1 | D3: =VLOOKUP(B3,dados!A$23:E$422,5,0) -> 9 | E3: =COUNTIF(C$2:C3,1) -> 2 | F3: =COUNTIF(C$2:C3,2) -> 0 | G3: =COUNTIF(C$2:C3,3) -> 0 | I3: 2 | J3: =COUNTIF(dados!$A$1:$T$20,I3) -> 71 | M3: =(AP3*$J2+AU3*$J3+AZ3*$J4)/SUM($J2:$J4) -> 13.7975 | N3: =(AQ3*$J2+AV3*$J3+BA3*$J4)/SUM($J2:$J4) -> 14.085 | O3: =(AR3*$J2+AW3*$J3+BB3*$J4)/SUM($J2:$J4) -> 14.590472 | P3: =(AS3*$J2+AX3*$J3+BC3*$J4)/SUM($J2:$J4) -> 14.54791 | R3: min | S3: {=MIN(IF(M4:M1003>(S4-1.5*(S6-S4)),M4:M1003,S4))} -> 11.24875 | T3: {=MIN(IF(N4:N1003>(T4-1.5*(T6-T4)),N4:N1003,T4))} -> 12.19375 | U3: {=MIN(IF(O4:O1003>(U4-1.5*(U6-U4)),O4:O1003,U4))} -> 12.609097 | V3: {=MIN(IF(P4:P1003>(V4-1.5*(V6-V4)),P4:P1003,V4))} -> 13.13184 | X3: 0.75 | Y3: =S7 -> 16.95375 | Z3: =X3+1 -> 1.75 | AA3: =T7 -> 15.90625 | AB3: =Z3+1 -> 2.75 | AC3: =U7 -> 15.309458 | AD3: =AB3+1 -> 3.75 | AE3: =V7 -> 14.87391 | AP3: =AVERAGEIFS(D:D,C:C,"1",E:E,CONCATENATE("<=",J7)) -> 8.8571429 | AQ3: =AVERAGEIFS(D:D,C:C,"1",E:E,CONCATENATE("<=",J12)) -> 10 | AR3: =AVERAGEIFS(D:D,C:C,"1",E:E,CONCATENATE("<=",J17)) -> 10.388889 | AS3: =AVERAGEIFS(D:D,C:C,"1",E:E,CONCATENATE("<=",J22)) -> 10.180556 | AU3: =AVERAGEIFS(D:D,C:C,"2",F:F,CONCATENATE("<=",J8)) -> 23 | AV3: =AVERAGEIFS(D:D,C:C,"2",F:F,CONCATENATE("<=",J13)) -> 20 | AW3: =AVERAGEIFS(D:D,C:C,"2",F:F,CONCATENATE("<=",J18)) -> 22.222222 | AX3: =AVERAGEIFS(D:D,C:C,"2",F:F,CONCATENATE("<=",J23)) -> 22.055556 | AZ3: =AVERAGEIFS(D:D,C:C,"3",G:G,CONCATENATE("<=",J9)) -> 32 | BA3: =AVERAGEIFS(D:D,C:C,"3",G:G,CONCATENATE("<=",J14)) -> 32 | BB3: =AVERAGEIFS(D:D,C:C,"3",G:G,CONCATENATE("<=",J19)) -> 30.4 | BC3: =AVERAGEIFS(D:D,C:C,"3",G:G,CONCATENATE("<=",J24)) -> 31.7
A4: 3 | B4: =SMALL(dados!A$23:A$422,A4) -> 0.0040107505 | C4: =VLOOKUP(B4,dados!A$23:E$422,4,0) -> 1 | D4: =VLOOKUP(B4,dados!A$23:E$422,5,0) -> 6 | E4: =COUNTIF(C$2:C4,1) -> 3 | F4: =COUNTIF(C$2:C4,2) -> 0 | G4: =COUNTIF(C$2:C4,3) -> 0 | I4: 3 | J4: =COUNTIF(dados!$A$1:$T$20,I4) -> 42 | L4: 1 | M4: 14.7175 | N4: 13.89125 | O4: 14.524 | P4: 14.315729 | R4: 1q | S4: =_xlfn.QUARTILE.INC(M4:M1003,1) -> 13.299688 | T4: =_xlfn.QUARTILE.INC(N4:N1003,1) -> 13.558594 | U4: =_xlfn.QUARTILE.INC(O4:O1003,1) -> 13.651035 | V4: =_xlfn.QUARTILE.INC(P4:P1003,1) -> 13.785655 | X4: 1 | Y4: =Y3 -> 16.95375 | Z4: =X4+1 -> 2 | AA4: =AA3 -> 15.90625 | AB4: =Z4+1 -> 3 | AC4: =AC3 -> 15.309458 | AD4: =AB4+1 -> 4 | AE4: =AE3 -> 14.87391 | AG4: 1 | AH4: =IF(OR(M4<S$3,M4>S$7),M4,#N/A) -> #N/A | AI4: =AG4+1 -> 2 | AJ4: =IF(OR(N4<T$3,N4>T$7),N4,#N/A) -> #N/A | AK4: =AI4+1 -> 3 | AL4: =IF(OR(O4<U$3,O4>U$7),O4,#N/A) -> #N/A | AM4: =AK4+1 -> 4 | AN4: =IF(OR(P4<V$3,P4>V$7),P4,#N/A) -> #N/A
A5: 4 | B5: =SMALL(dados!A$23:A$422,A5) -> 0.0082381268 | C5: =VLOOKUP(B5,dados!A$23:E$422,4,0) -> 1 | D5: =VLOOKUP(B5,dados!A$23:E$422,5,0) -> 15 | E5: =COUNTIF(C$2:C5,1) -> 4 | F5: =COUNTIF(C$2:C5,2) -> 0 | G5: =COUNTIF(C$2:C5,3) -> 0 | L5: 2 | M5: 13.06 | N5: 13.756875 | O5: 13.635056 | P5: 14.11009 | R5: med | S5: =MEDIAN(M4:M1003) -> 14.011875 | T5: =MEDIAN(N4:N1003) -> 14.029687 | U5: =MEDIAN(O4:O1003) -> 14.03759 | V5: =MEDIAN(P4:P1003) -> 14.021573 | X5: 1 | Y5: =S6 -> 14.798125 | Z5: =X5+1 -> 2 | AA5: =T6 -> 14.503438 | AB5: =Z5+1 -> 3 | AC5: =U6 -> 14.363538 | AD5: =AB5+1 -> 4 | AE5: =V6 -> 14.244063 | AG5: 1 | AH5: =IF(OR(M5<S$3,M5>S$7),M5,#N/A) -> #N/A | AI5: =AG5+1 -> 2 | AJ5: =IF(OR(N5<T$3,N5>T$7),N5,#N/A) -> #N/A | AK5: =AI5+1 -> 3 | AL5: =IF(OR(O5<U$3,O5>U$7),O5,#N/A) -> #N/A | AM5: =AK5+1 -> 4 | AN5: =IF(OR(P5<V$3,P5>V$7),P5,#N/A) -> #N/A
A6: 5 | B6: =SMALL(dados!A$23:A$422,A6) -> 0.0092508416 | C6: =VLOOKUP(B6,dados!A$23:E$422,4,0) -> 3 | D6: =VLOOKUP(B6,dados!A$23:E$422,5,0) -> 28 | E6: =COUNTIF(C$2:C6,1) -> 4 | F6: =COUNTIF(C$2:C6,2) -> 0 | G6: =COUNTIF(C$2:C6,3) -> 1 | J6: #11 | L6: 3 | M6: 13.18125 | N6: 13.37625 | O6: 14.270931 | P6: 14.01941 | R6: 3q | S6: =_xlfn.QUARTILE.INC(M4:M1003,3) -> 14.798125 | T6: =_xlfn.QUARTILE.INC(N4:N1003,3) -> 14.503438 | U6: =_xlfn.QUARTILE.INC(O4:O1003,3) -> 14.363538 | V6: =_xlfn.QUARTILE.INC(P4:P1003,3) -> 14.244063 | X6: 0.75 | Y6: =Y5 -> 14.798125 | Z6: =X6+1 -> 1.75 | AA6: =AA5 -> 14.503438 | AB6: =Z6+1 -> 2.75 | AC6: =AC5 -> 14.363538 | AD6: =AB6+1 -> 3.75 | AE6: =AE5 -> 14.244063 | AG6: 1 | AH6: =IF(OR(M6<S$3,M6>S$7),M6,#N/A) -> #N/A | AI6: =AG6+1 -> 2 | AJ6: =IF(OR(N6<T$3,N6>T$7),N6,#N/A) -> #N/A | AK6: =AI6+1 -> 3 | AL6: =IF(OR(O6<U$3,O6>U$7),O6,#N/A) -> #N/A | AM6: =AK6+1 -> 4 | AN6: =IF(OR(P6<V$3,P6>V$7),P6,#N/A) -> #N/A
A7: 6 | B7: =SMALL(dados!A$23:A$422,A7) -> 0.014387824 | C7: =VLOOKUP(B7,dados!A$23:E$422,4,0) -> 2 | D7: =VLOOKUP(B7,dados!A$23:E$422,5,0) -> 26 | E7: =COUNTIF(C$2:C7,1) -> 4 | F7: =COUNTIF(C$2:C7,2) -> 1 | G7: =COUNTIF(C$2:C7,3) -> 1 | I7: 1 | J7: 7 | L7: 4 | M7: 12.8925 | N7: 12.834375 | O7: 13.935792 | P7: 13.636764 | R7: max | S7: {=MAX(IF(M4:M1003<(S6+1.5*(S6-S4)),M4:M1003,S6))} -> 16.95375 | T7: {=MAX(IF(N4:N1003<(T6+1.5*(T6-T4)),N4:N1003,T6))} -> 15.90625 | U7: {=MAX(IF(O4:O1003<(U6+1.5*(U6-U4)),O4:O1003,U6))} -> 15.309458 | V7: {=MAX(IF(P4:P1003<(V6+1.5*(V6-V4)),P4:P1003,V6))} -> 14.87391 | X7: 0.75 | Y7: =S5 -> 14.011875 | Z7: =X7+1 -> 1.75 | AA7: =T5 -> 14.029687 | AB7: =Z7+1 -> 2.75 | AC7: =U5 -> 14.03759 | AD7: =AB7+1 -> 3.75 | AE7: =V5 -> 14.021573 | AG7: 1 | AH7: =IF(OR(M7<S$3,M7>S$7),M7,#N/A) -> #N/A | AI7: =AG7+1 -> 2 | AJ7: =IF(OR(N7<T$3,N7>T$7),N7,#N/A) -> #N/A | AK7: =AI7+1 -> 3 | AL7: =IF(OR(O7<U$3,O7>U$7),O7,#N/A) -> #N/A | AM7: =AK7+1 -> 4 | AN7: =IF(OR(P7<V$3,P7>V$7),P7,#N/A) -> #N/A
A8: 7 | B8: =SMALL(dados!A$23:A$422,A8) -> 0.015141544 | C8: =VLOOKUP(B8,dados!A$23:E$422,4,0) -> 1 | D8: =VLOOKUP(B8,dados!A$23:E$422,5,0) -> 7 | E8: =COUNTIF(C$2:C8,1) -> 5 | F8: =COUNTIF(C$2:C8,2) -> 1 | G8: =COUNTIF(C$2:C8,3) -> 1 | I8: 2 | J8: 2 | L8: 5 | M8: 15.22625 | N8: 14.2525 | O8: 13.950972 | P8: 14.021292 | X8: 1.25 | Y8: =Y7 -> 14.011875 | Z8: =X8+1 -> 2.25 | AA8: =AA7 -> 14.029687 | AB8: =Z8+1 -> 3.25 | AC8: =AC7 -> 14.03759 | AD8: =AB8+1 -> 4.25 | AE8: =AE7 -> 14.021573 | AG8: 1 | AH8: =IF(OR(M8<S$3,M8>S$7),M8,#N/A) -> #N/A | AI8: =AG8+1 -> 2 | AJ8: =IF(OR(N8<T$3,N8>T$7),N8,#N/A) -> #N/A | AK8: =AI8+1 -> 3 | AL8: =IF(OR(O8<U$3,O8>U$7),O8,#N/A) -> #N/A | AM8: =AK8+1 -> 4 | AN8: =IF(OR(P8<V$3,P8>V$7),P8,#N/A) -> #N/A
A9: 8 | B9: =SMALL(dados!A$23:A$422,A9) -> 0.016365066 | C9: =VLOOKUP(B9,dados!A$23:E$422,4,0) -> 1 | D9: =VLOOKUP(B9,dados!A$23:E$422,5,0) -> 11 | E9: =COUNTIF(C$2:C9,1) -> 6 | F9: =COUNTIF(C$2:C9,2) -> 1 | G9: =COUNTIF(C$2:C9,3) -> 1 | I9: 3 | J9: 2 | L9: 6 | M9: 15.12625 | N9: 14.05 | O9: 13.991014 | P9: 14.52425 | X9: 1.25 | Y9: =S4 -> 13.299688 | Z9: =X9+1 -> 2.25 | AA9: =T4 -> 13.558594 | AB9: =Z9+1 -> 3.25 | AC9: =U4 -> 13.651035 | AD9: =AB9+1 -> 4.25 | AE9: =V4 -> 13.785655 | AG9: 1 | AH9: =IF(OR(M9<S$3,M9>S$7),M9,#N/A) -> #N/A | AI9: =AG9+1 -> 2 | AJ9: =IF(OR(N9<T$3,N9>T$7),N9,#N/A) -> #N/A | AK9: =AI9+1 -> 3 | AL9: =IF(OR(O9<U$3,O9>U$7),O9,#N/A) -> #N/A | AM9: =AK9+1 -> 4 | AN9: =IF(OR(P9<V$3,P9>V$7),P9,#N/A) -> #N/A
A10: 9 | B10: =SMALL(dados!A$23:A$422,A10) -> 0.024876855 | C10: =VLOOKUP(B10,dados!A$23:E$422,4,0) -> 1 | D10: =VLOOKUP(B10,dados!A$23:E$422,5,0) -> 5 | E10: =COUNTIF(C$2:C10,1) -> 7 | F10: =COUNTIF(C$2:C10,2) -> 1 | G10: =COUNTIF(C$2:C10,3) -> 1 | L10: 7 | M10: 14.6475 | N10: 14.695625 | O10: 14.241083 | P10: 14.325146 | X10: 1 | Y10: =Y9 -> 13.299688 | Z10: =X10+1 -> 2 | AA10: =AA9 -> 13.558594 | AB10: =Z10+1 -> 3 | AC10: =AC9 -> 13.651035 | AD10: =AB10+1 -> 4 | AE10: =AE9 -> 13.785655 | AG10: 1 | AH10: =IF(OR(M10<S$3,M10>S$7),M10,#N/A) -> #N/A | AI10: =AG10+1 -> 2 | AJ10: =IF(OR(N10<T$3,N10>T$7),N10,#N/A) -> #N/A | AK10: =AI10+1 -> 3 | AL10: =IF(OR(O10<U$3,O10>U$7),O10,#N/A) -> #N/A | AM10: =AK10+1 -> 4 | AN10: =IF(OR(P10<V$3,P10>V$7),P10,#N/A) -> #N/A
A11: 10 | B11: =SMALL(dados!A$23:A$422,A11) -> 0.028372084 | C11: =VLOOKUP(B11,dados!A$23:E$422,4,0) -> 2 | D11: =VLOOKUP(B11,dados!A$23:E$422,5,0) -> 20 | E11: =COUNTIF(C$2:C11,1) -> 7 | F11: =COUNTIF(C$2:C11,2) -> 2 | G11: =COUNTIF(C$2:C11,3) -> 1 | J11: #20 | L11: 8 | M11: 14.81 | N11: 14.618125 | O11: 15.151875 | P11: 14.164875 | X11: 1 | Y11: =S3 -> 11.24875 | Z11: =X11+1 -> 2 | AA11: =T3 -> 12.19375 | AB11: =Z11+1 -> 3 | AC11: =U3 -> 12.609097 | AD11: =AB11+1 -> 4 | AE11: =V3 -> 13.13184 | AG11: 1 | AH11: =IF(OR(M11<S$3,M11>S$7),M11,#N/A) -> #N/A | AI11: =AG11+1 -> 2 | AJ11: =IF(OR(N11<T$3,N11>T$7),N11,#N/A) -> #N/A | AK11: =AI11+1 -> 3 | AL11: =IF(OR(O11<U$3,O11>U$7),O11,#N/A) -> #N/A | AM11: =AK11+1 -> 4 | AN11: =IF(OR(P11<V$3,P11>V$7),P11,#N/A) -> #N/A
A12: 11 | B12: =SMALL(dados!A$23:A$422,A12) -> 0.030016192 | C12: =VLOOKUP(B12,dados!A$23:E$422,4,0) -> 1 | D12: =VLOOKUP(B12,dados!A$23:E$422,5,0) -> 10 | E12: =COUNTIF(C$2:C12,1) -> 8 | F12: =COUNTIF(C$2:C12,2) -> 2 | G12: =COUNTIF(C$2:C12,3) -> 1 | I12: 1 | J12: 14 | L12: 9 | M12: 13.67375 | N12: 14.370625 | O12: 14.610167 | P12: 14.642736 | X12: 1.25 | Y12: =Y11 -> 11.24875 | Z12: =X12+1 -> 2.25 | AA12: =AA11 -> 12.19375 | AB12: =Z12+1 -> 3.25 | AC12: =AC11 -> 12.609097 | AD12: =AB12+1 -> 4.25 | AE12: =AE11 -> 13.13184 | AG12: 1 | AH12: =IF(OR(M12<S$3,M12>S$7),M12,#N/A) -> #N/A | AI12: =AG12+1 -> 2 | AJ12: =IF(OR(N12<T$3,N12>T$7),N12,#N/A) -> #N/A | AK12: =AI12+1 -> 3 | AL12: =IF(OR(O12<U$3,O12>U$7),O12,#N/A) -> #N/A | AM12: =AK12+1 -> 4 | AN12: =IF(OR(P12<V$3,P12>V$7),P12,#N/A) -> #N/A
A13: 12 | B13: =SMALL(dados!A$23:A$422,A13) -> 0.030558105 | C13: =VLOOKUP(B13,dados!A$23:E$422,4,0) -> 1 | D13: =VLOOKUP(B13,dados!A$23:E$422,5,0) -> 9 | E13: =COUNTIF(C$2:C13,1) -> 9 | F13: =COUNTIF(C$2:C13,2) -> 2 | G13: =COUNTIF(C$2:C13,3) -> 1 | I13: 2 | J13: 4 | L13: 10 | M13: 15.16875 | N13: 15.278125 | O13: 14.465694 | P13: 14.630646 | X13: 0.75 | Y13: =Y11 -> 11.24875 | Z13: =X13+1 -> 1.75 | AA13: =AA11 -> 12.19375 | AB13: =Z13+1 -> 2.75 | AC13: =AC11 -> 12.609097 | AD13: =AB13+1 -> 3.75 | AE13: =AE11 -> 13.13184 | AG13: 1 | AH13: =IF(OR(M13<S$3,M13>S$7),M13,#N/A) -> #N/A | AI13: =AG13+1 -> 2 | AJ13: =IF(OR(N13<T$3,N13>T$7),N13,#N/A) -> #N/A | AK13: =AI13+1 -> 3 | AL13: =IF(OR(O13<U$3,O13>U$7),O13,#N/A) -> #N/A | AM13: =AK13+1 -> 4 | AN13: =IF(OR(P13<V$3,P13>V$7),P13,#N/A) -> #N/A
A14: 13 | B14: =SMALL(dados!A$23:A$422,A14) -> 0.032498109 | C14: =VLOOKUP(B14,dados!A$23:E$422,4,0) -> 2 | D14: =VLOOKUP(B14,dados!A$23:E$422,5,0) -> 13 | E14: =COUNTIF(C$2:C14,1) -> 9 | F14: =COUNTIF(C$2:C14,2) -> 3 | G14: =COUNTIF(C$2:C14,3) -> 1 | I14: 3 | J14: 2 | L14: 11 | M14: 16.25875 | N14: 14.3425 | O14: 14.143028 | P14: 14.022854 | X14: 1 | Y14: =Y13 -> 11.24875 | Z14: =X14+1 -> 2 | AA14: =AA13 -> 12.19375 | AB14: =Z14+1 -> 3 | AC14: =AC13 -> 12.609097 | AD14: =AB14+1 -> 4 | AE14: =AE13 -> 13.13184 | AG14: 1 | AH14: =IF(OR(M14<S$3,M14>S$7),M14,#N/A) -> #N/A | AI14: =AG14+1 -> 2 | AJ14: =IF(OR(N14<T$3,N14>T$7),N14,#N/A) -> #N/A | AK14: =AI14+1 -> 3 | AL14: =IF(OR(O14<U$3,O14>U$7),O14,#N/A) -> #N/A | AM14: =AK14+1 -> 4 | AN14: =IF(OR(P14<V$3,P14>V$7),P14,#N/A) -> #N/A
A15: 14 | B15: =SMALL(dados!A$23:A$422,A15) -> 0.033442967 | C15: =VLOOKUP(B15,dados!A$23:E$422,4,0) -> 3 | D15: =VLOOKUP(B15,dados!A$23:E$422,5,0) -> 36 | E15: =COUNTIF(C$2:C15,1) -> 9 | F15: =COUNTIF(C$2:C15,2) -> 3 | G15: =COUNTIF(C$2:C15,3) -> 2 | L15: 12 | M15: 13.8175 | N15: 13.845 | O15: 13.971028 | P15: 14.431563 | X15: 1 | Y15: =Y9 -> 13.299688 | Z15: =X15+1 -> 2 | AA15: =AA9 -> 13.558594 | AB15: =Z15+1 -> 3 | AC15: =AC9 -> 13.651035 | AD15: =AB15+1 -> 4 | AE15: =AE9 -> 13.785655 | AG15: 1 | AH15: =IF(OR(M15<S$3,M15>S$7),M15,#N/A) -> #N/A | AI15: =AG15+1 -> 2 | AJ15: =IF(OR(N15<T$3,N15>T$7),N15,#N/A) -> #N/A | AK15: =AI15+1 -> 3 | AL15: =IF(OR(O15<U$3,O15>U$7),O15,#N/A) -> #N/A | AM15: =AK15+1 -> 4 | AN15: =IF(OR(P15<V$3,P15>V$7),P15,#N/A) -> #N/A
A16: 15 | B16: =SMALL(dados!A$23:A$422,A16) -> 0.040481216 | C16: =VLOOKUP(B16,dados!A$23:E$422,4,0) -> 1 | D16: =VLOOKUP(B16,dados!A$23:E$422,5,0) -> 14 | E16: =COUNTIF(C$2:C16,1) -> 10 | F16: =COUNTIF(C$2:C16,2) -> 3 | G16: =COUNTIF(C$2:C16,3) -> 2 | J16: #50 | L16: 13 | M16: 14.0875 | N16: 14.938125 | O16: 13.980736 | P16: 14.286972 | X16: 0.75 | Y16: =Y15 -> 13.299688 | Z16: =X16+1 -> 1.75 | AA16: =AA15 -> 13.558594 | AB16: =Z16+1 -> 2.75 | AC16: =AC15 -> 13.651035 | AD16: =AB16+1 -> 3.75 | AE16: =AE15 -> 13.785655 | AG16: 1 | AH16: =IF(OR(M16<S$3,M16>S$7),M16,#N/A) -> #N/A | AI16: =AG16+1 -> 2 | AJ16: =IF(OR(N16<T$3,N16>T$7),N16,#N/A) -> #N/A | AK16: =AI16+1 -> 3 | AL16: =IF(OR(O16<U$3,O16>U$7),O16,#N/A) -> #N/A | AM16: =AK16+1 -> 4 | AN16: =IF(OR(P16<V$3,P16>V$7),P16,#N/A) -> #N/A
A17: 16 | B17: =SMALL(dados!A$23:A$422,A17) -> 0.043259559 | C17: =VLOOKUP(B17,dados!A$23:E$422,4,0) -> 2 | D17: =VLOOKUP(B17,dados!A$23:E$422,5,0) -> 21 | E17: =COUNTIF(C$2:C17,1) -> 10 | F17: =COUNTIF(C$2:C17,2) -> 4 | G17: =COUNTIF(C$2:C17,3) -> 2 | I17: 1 | J17: 36 | L17: 14 | M17: 14.45625 | N17: 14.00875 | O17: 13.426181 | P17: 13.714701 | X17: 0.75 | Y17: =Y7 -> 14.011875 | Z17: =X17+1 -> 1.75 | AA17: =AA7 -> 14.029687 | AB17: =Z17+1 -> 2.75 | AC17: =AC7 -> 14.03759 | AD17: =AB17+1 -> 3.75 | AE17: =AE7 -> 14.021573 | AG17: 1 | AH17: =IF(OR(M17<S$3,M17>S$7),M17,#N/A) -> #N/A | AI17: =AG17+1 -> 2 | AJ17: =IF(OR(N17<T$3,N17>T$7),N17,#N/A) -> #N/A | AK17: =AI17+1 -> 3 | AL17: =IF(OR(O17<U$3,O17>U$7),O17,#N/A) -> #N/A | AM17: =AK17+1 -> 4 | AN17: =IF(OR(P17<V$3,P17>V$7),P17,#N/A) -> #N/A
A18: 17 | B18: =SMALL(dados!A$23:A$422,A18) -> 0.043299396 | C18: =VLOOKUP(B18,dados!A$23:E$422,4,0) -> 3 | D18: =VLOOKUP(B18,dados!A$23:E$422,5,0) -> 20 | E18: =COUNTIF(C$2:C18,1) -> 10 | F18: =COUNTIF(C$2:C18,2) -> 4 | G18: =COUNTIF(C$2:C18,3) -> 3 | I18: 2 | J18: 9 | L18: 15 | M18: 14.86 | N18: 14.811875 | O18: 14.298181 | P18: 14.327507 | X18: 1.25 | Y18: =Y17 -> 14.011875 | Z18: =X18+1 -> 2.25 | AA18: =AA17 -> 14.029687 | AB18: =Z18+1 -> 3.25 | AC18: =AC17 -> 14.03759 | AD18: =AB18+1 -> 4.25 | AE18: =AE17 -> 14.021573 | AG18: 1 | AH18: =IF(OR(M18<S$3,M18>S$7),M18,#N/A) -> #N/A | AI18: =AG18+1 -> 2 | AJ18: =IF(OR(N18<T$3,N18>T$7),N18,#N/A) -> #N/A | AK18: =AI18+1 -> 3 | AL18: =IF(OR(O18<U$3,O18>U$7),O18,#N/A) -> #N/A | AM18: =AK18+1 -> 4 | AN18: =IF(OR(P18<V$3,P18>V$7),P18,#N/A) -> #N/A
A19: 18 | B19: =SMALL(dados!A$23:A$422,A19) -> 0.047114437 | C19: =VLOOKUP(B19,dados!A$23:E$422,4,0) -> 1 | D19: =VLOOKUP(B19,dados!A$23:E$422,5,0) -> 11 | E19: =COUNTIF(C$2:C19,1) -> 11 | F19: =COUNTIF(C$2:C19,2) -> 4 | G19: =COUNTIF(C$2:C19,3) -> 3 | I19: 3 | J19: 5 | L19: 16 | M19: 14.3175 | N19: 14.22875 | O19: 14.419056 | P19: 14.304347 | X19: 1.25 | Y19: =Y5 -> 14.798125 | Z19: =X19+1 -> 2.25 | AA19: =AA5 -> 14.503438 | AB19: =Z19+1 -> 3.25 | AC19: =AC5 -> 14.363538 | AD19: =AB19+1 -> 4.25 | AE19: =AE5 -> 14.244063 | AG19: 1 | AH19: =IF(OR(M19<S$3,M19>S$7),M19,#N/A) -> #N/A | AI19: =AG19+1 -> 2 | AJ19: =IF(OR(N19<T$3,N19>T$7),N19,#N/A) -> #N/A | AK19: =AI19+1 -> 3 | AL19: =IF(OR(O19<U$3,O19>U$7),O19,#N/A) -> #N/A | AM19: =AK19+1 -> 4 | AN19: =IF(OR(P19<V$3,P19>V$7),P19,#N/A) -> #N/A
A20: 19 | B20: =SMALL(dados!A$23:A$422,A20) -> 0.048803968 | C20: =VLOOKUP(B20,dados!A$23:E$422,4,0) -> 1 | D20: =VLOOKUP(B20,dados!A$23:E$422,5,0) -> 15 | E20: =COUNTIF(C$2:C20,1) -> 12 | F20: =COUNTIF(C$2:C20,2) -> 4 | G20: =COUNTIF(C$2:C20,3) -> 3 | L20: 17 | M20: 14.42375 | N20: 14.6525 | O20: 14.340194 | P20: 14.029361 | X20: 1 | Y20: =Y19 -> 14.798125 | Z20: =X20+1 -> 2 | AA20: =AA19 -> 14.503438 | AB20: =Z20+1 -> 3 | AC20: =AC19 -> 14.363538 | AD20: =AB20+1 -> 4 | AE20: =AE19 -> 14.244063 | AG20: 1 | AH20: =IF(OR(M20<S$3,M20>S$7),M20,#N/A) -> #N/A | AI20: =AG20+1 -> 2 | AJ20: =IF(OR(N20<T$3,N20>T$7),N20,#N/A) -> #N/A | AK20: =AI20+1 -> 3 | AL20: =IF(OR(O20<U$3,O20>U$7),O20,#N/A) -> #N/A | AM20: =AK20+1 -> 4 | AN20: =IF(OR(P20<V$3,P20>V$7),P20,#N/A) -> #N/A
A21: 20 | B21: =SMALL(dados!A$23:A$422,A21) -> 0.049208211 | C21: =VLOOKUP(B21,dados!A$23:E$422,4,0) -> 1 | D21: =VLOOKUP(B21,dados!A$23:E$422,5,0) -> 5 | E21: =COUNTIF(C$2:C21,1) -> 13 | F21: =COUNTIF(C$2:C21,2) -> 4 | G21: =COUNTIF(C$2:C21,3) -> 3 | J21: #100 | L21: 18 | M21: 13.74125 | N21: 13.915 | O21: 14.514819 | P21: 13.932354 | X21: 1 | Y21: =Y3 -> 16.95375 | Z21: =X21+1 -> 2 | AA21: =AA3 -> 15.90625 | AB21: =Z21+1 -> 3 | AC21: =AC3 -> 15.309458 | AD21: =AB21+1 -> 4 | AE21: =AE3 -> 14.87391 | AG21: 1 | AH21: =IF(OR(M21<S$3,M21>S$7),M21,#N/A) -> #N/A | AI21: =AG21+1 -> 2 | AJ21: =IF(OR(N21<T$3,N21>T$7),N21,#N/A) -> #N/A | AK21: =AI21+1 -> 3 | AL21: =IF(OR(O21<U$3,O21>U$7),O21,#N/A) -> #N/A | AM21: =AK21+1 -> 4 | AN21: =IF(OR(P21<V$3,P21>V$7),P21,#N/A) -> #N/A
A22: 21 | B22: =SMALL(dados!A$23:A$422,A22) -> 0.056803862 | C22: =VLOOKUP(B22,dados!A$23:E$422,4,0) -> 2 | D22: =VLOOKUP(B22,dados!A$23:E$422,5,0) -> 17 | E22: =COUNTIF(C$2:C22,1) -> 13 | F22: =COUNTIF(C$2:C22,2) -> 5 | G22: =COUNTIF(C$2:C22,3) -> 3 | I22: 1 | J22: 72 | L22: 19 | M22: 14.5225 | N22: 14.365625 | O22: 14.717569 | P22: 14.563604 | X22: 1.25 | Y22: =Y3 -> 16.95375 | Z22: =X22+1 -> 2.25 | AA22: =AA3 -> 15.90625 | AB22: =Z22+1 -> 3.25 | AC22: =AC3 -> 15.309458 | AD22: =AB22+1 -> 4.25 | AE22: =AE3 -> 14.87391 | AG22: 1 | AH22: =IF(OR(M22<S$3,M22>S$7),M22,#N/A) -> #N/A | AI22: =AG22+1 -> 2 | AJ22: =IF(OR(N22<T$3,N22>T$7),N22,#N/A) -> #N/A | AK22: =AI22+1 -> 3 | AL22: =IF(OR(O22<U$3,O22>U$7),O22,#N/A) -> #N/A | AM22: =AK22+1 -> 4 | AN22: =IF(OR(P22<V$3,P22>V$7),P22,#N/A) -> #N/A
A23: 22 | B23: =SMALL(dados!A$23:A$422,A23) -> 0.060972481 | C23: =VLOOKUP(B23,dados!A$23:E$422,4,0) -> 3 | D23: =VLOOKUP(B23,dados!A$23:E$422,5,0) -> 35 | E23: =COUNTIF(C$2:C23,1) -> 13 | F23: =COUNTIF(C$2:C23,2) -> 5 | G23: =COUNTIF(C$2:C23,3) -> 4 | I23: 2 | J23: 18 | L23: 20 | M23: 13.95875 | N23: 14.30375 | O23: 13.438847 | P23: 13.838403 | AG23: 1 | AH23: =IF(OR(M23<S$3,M23>S$7),M23,#N/A) -> #N/A | AI23: =AG23+1 -> 2 | AJ23: =IF(OR(N23<T$3,N23>T$7),N23,#N/A) -> #N/A | AK23: =AI23+1 -> 3 | AL23: =IF(OR(O23<U$3,O23>U$7),O23,#N/A) -> #N/A | AM23: =AK23+1 -> 4 | AN23: =IF(OR(P23<V$3,P23>V$7),P23,#N/A) -> #N/A
A24: 23 | B24: =SMALL(dados!A$23:A$422,A24) -> 0.066785324 | C24: =VLOOKUP(B24,dados!A$23:E$422,4,0) -> 1 | D24: =VLOOKUP(B24,dados!A$23:E$422,5,0) -> 14 | E24: =COUNTIF(C$2:C24,1) -> 14 | F24: =COUNTIF(C$2:C24,2) -> 5 | G24: =COUNTIF(C$2:C24,3) -> 4 | I24: 3 | J24: 10 | L24: 21 | M24: 15.45625 | N24: 15.7975 | O24: 14.700014 | P24: 14.140118 | AG24: 1 | AH24: =IF(OR(M24<S$3,M24>S$7),M24,#N/A) -> #N/A | AI24: =AG24+1 -> 2 | AJ24: =IF(OR(N24<T$3,N24>T$7),N24,#N/A) -> #N/A | AK24: =AI24+1 -> 3 | AL24: =IF(OR(O24<U$3,O24>U$7),O24,#N/A) -> #N/A | AM24: =AK24+1 -> 4 | AN24: =IF(OR(P24<V$3,P24>V$7),P24,#N/A) -> #N/A
A25: 24 | B25: =SMALL(dados!A$23:A$422,A25) -> 0.066839328 | C25: =VLOOKUP(B25,dados!A$23:E$422,4,0) -> 1 | D25: =VLOOKUP(B25,dados!A$23:E$422,5,0) -> 16 | E25: =COUNTIF(C$2:C25,1) -> 15 | F25: =COUNTIF(C$2:C25,2) -> 5 | G25: =COUNTIF(C$2:C25,3) -> 4 | L25: 22 | M25: 15.72 | N25: 14.115 | O25: 14.161306 | P25: 13.837097 | AG25: 1 | AH25: =IF(OR(M25<S$3,M25>S$7),M25,#N/A) -> #N/A | AI25: =AG25+1 -> 2 | AJ25: =IF(OR(N25<T$3,N25>T$7),N25,#N/A) -> #N/A | AK25: =AI25+1 -> 3 | AL25: =IF(OR(O25<U$3,O25>U$7),O25,#N/A) -> #N/A | AM25: =AK25+1 -> 4 | AN25: =IF(OR(P25<V$3,P25>V$7),P25,#N/A) -> #N/A
A26: 25 | B26: =SMALL(dados!A$23:A$422,A26) -> 0.067138792 | C26: =VLOOKUP(B26,dados!A$23:E$422,4,0) -> 1 | D26: =VLOOKUP(B26,dados!A$23:E$422,5,0) -> 13 | E26: =COUNTIF(C$2:C26,1) -> 16 | F26: =COUNTIF(C$2:C26,2) -> 5 | G26: =COUNTIF(C$2:C26,3) -> 4 | L26: 23 | M26: 15.03 | N26: 14.97875 | O26: 14.293444 | P26: 14.391319 | AG26: 1 | AH26: =IF(OR(M26<S$3,M26>S$7),M26,#N/A) -> #N/A | AI26: =AG26+1 -> 2 | AJ26: =IF(OR(N26<T$3,N26>T$7),N26,#N/A) -> #N/A | AK26: =AI26+1 -> 3 | AL26: =IF(OR(O26<U$3,O26>U$7),O26,#N/A) -> #N/A | AM26: =AK26+1 -> 4 | AN26: =IF(OR(P26<V$3,P26>V$7),P26,#N/A) -> #N/A
A27: 26 | B27: =SMALL(dados!A$23:A$422,A27) -> 0.067823811 | C27: =VLOOKUP(B27,dados!A$23:E$422,4,0) -> 1 | D27: =VLOOKUP(B27,dados!A$23:E$422,5,0) -> 13 | E27: =COUNTIF(C$2:C27,1) -> 17 | F27: =COUNTIF(C$2:C27,2) -> 5 | G27: =COUNTIF(C$2:C27,3) -> 4 | L27: 24 | M27: 13.935 | N27: 13.72625 | O27: 14.076764 | P27: 14.371028 | AG27: 1 | AH27: =IF(OR(M27<S$3,M27>S$7),M27,#N/A) -> #N/A | AI27: =AG27+1 -> 2 | AJ27: =IF(OR(N27<T$3,N27>T$7),N27,#N/A) -> #N/A | AK27: =AI27+1 -> 3 | AL27: =IF(OR(O27<U$3,O27>U$7),O27,#N/A) -> #N/A | AM27: =AK27+1 -> 4 | AN27: =IF(OR(P27<V$3,P27>V$7),P27,#N/A) -> #N/A
A28: 27 | B28: =SMALL(dados!A$23:A$422,A28) -> 0.06809029 | C28: =VLOOKUP(B28,dados!A$23:E$422,4,0) -> 1 | D28: =VLOOKUP(B28,dados!A$23:E$422,5,0) -> 14 | E28: =COUNTIF(C$2:C28,1) -> 18 | F28: =COUNTIF(C$2:C28,2) -> 5 | G28: =COUNTIF(C$2:C28,3) -> 4 | L28: 25 | M28: 15.355 | N28: 14.163125 | O28: 13.984861 | P28: 14.128569 | AG28: 1 | AH28: =IF(OR(M28<S$3,M28>S$7),M28,#N/A) -> #N/A | AI28: =AG28+1 -> 2 | AJ28: =IF(OR(N28<T$3,N28>T$7),N28,#N/A) -> #N/A | AK28: =AI28+1 -> 3 | AL28: =IF(OR(O28<U$3,O28>U$7),O28,#N/A) -> #N/A | AM28: =AK28+1 -> 4 | AN28: =IF(OR(P28<V$3,P28>V$7),P28,#N/A) -> #N/A
A29: 28 | B29: =SMALL(dados!A$23:A$422,A29) -> 0.069020494 | C29: =VLOOKUP(B29,dados!A$23:E$422,4,0) -> 1 | D29: =VLOOKUP(B29,dados!A$23:E$422,5,0) -> 9 | E29: =COUNTIF(C$2:C29,1) -> 19 | F29: =COUNTIF(C$2:C29,2) -> 5 | G29: =COUNTIF(C$2:C29,3) -> 4 | L29: 26 | M29: 14.79625 | N29: 14.420625 | O29: 13.962111 | P29: 13.464653 | AG29: 1 | AH29: =IF(OR(M29<S$3,M29>S$7),M29,#N/A) -> #N/A | AI29: =AG29+1 -> 2 | AJ29: =IF(OR(N29<T$3,N29>T$7),N29,#N/A) -> #N/A | AK29: =AI29+1 -> 3 | AL29: =IF(OR(O29<U$3,O29>U$7),O29,#N/A) -> #N/A | AM29: =AK29+1 -> 4 | AN29: =IF(OR(P29<V$3,P29>V$7),P29,#N/A) -> #N/A
A30: 29 | B30: =SMALL(dados!A$23:A$422,A30) -> 0.071655917 | C30: =VLOOKUP(B30,dados!A$23:E$422,4,0) -> 1 | D30: =VLOOKUP(B30,dados!A$23:E$422,5,0) -> 8 | E30: =COUNTIF(C$2:C30,1) -> 20 | F30: =COUNTIF(C$2:C30,2) -> 5 | G30: =COUNTIF(C$2:C30,3) -> 4 | L30: 27 | M30: 14.0925 | N30: 14.2975 | O30: 14.501306 | P30: 14.244854 | AG30: 1 | AH30: =IF(OR(M30<S$3,M30>S$7),M30,#N/A) -> #N/A | AI30: =AG30+1 -> 2 | AJ30: =IF(OR(N30<T$3,N30>T$7),N30,#N/A) -> #N/A | AK30: =AI30+1 -> 3 | AL30: =IF(OR(O30<U$3,O30>U$7),O30,#N/A) -> #N/A | AM30: =AK30+1 -> 4 | AN30: =IF(OR(P30<V$3,P30>V$7),P30,#N/A) -> #N/A
A31: 30 | B31: =SMALL(dados!A$23:A$422,A31) -> 0.072901778 | C31: =VLOOKUP(B31,dados!A$23:E$422,4,0) -> 1 | D31: =VLOOKUP(B31,dados!A$23:E$422,5,0) -> 13 | E31: =COUNTIF(C$2:C31,1) -> 21 | F31: =COUNTIF(C$2:C31,2) -> 5 | G31: =COUNTIF(C$2:C31,3) -> 4 | L31: 28 | M31: 13.6375 | N31: 12.77625 | O31: 13.639125 | P31: 13.757687 | AG31: 1 | AH31: =IF(OR(M31<S$3,M31>S$7),M31,#N/A) -> #N/A | AI31: =AG31+1 -> 2 | AJ31: =IF(OR(N31<T$3,N31>T$7),N31,#N/A) -> #N/A | AK31: =AI31+1 -> 3 | AL31: =IF(OR(O31<U$3,O31>U$7),O31,#N/A) -> #N/A | AM31: =AK31+1 -> 4 | AN31: =IF(OR(P31<V$3,P31>V$7),P31,#N/A) -> #N/A
A32: 31 | B32: =SMALL(dados!A$23:A$422,A32) -> 0.075074353 | C32: =VLOOKUP(B32,dados!A$23:E$422,4,0) -> 1 | D32: =VLOOKUP(B32,dados!A$23:E$422,5,0) -> 9 | E32: =COUNTIF(C$2:C32,1) -> 22 | F32: =COUNTIF(C$2:C32,2) -> 5 | G32: =COUNTIF(C$2:C32,3) -> 4 | L32: 29 | M32: 12.82625 | N32: 13.1475 | O32: 13.621375 | P32: 13.787035 | AG32: 1 | AH32: =IF(OR(M32<S$3,M32>S$7),M32,#N/A) -> #N/A | AI32: =AG32+1 -> 2 | AJ32: =IF(OR(N32<T$3,N32>T$7),N32,#N/A) -> #N/A | AK32: =AI32+1 -> 3 | AL32: =IF(OR(O32<U$3,O32>U$7),O32,#N/A) -> #N/A | AM32: =AK32+1 -> 4 | AN32: =IF(OR(P32<V$3,P32>V$7),P32,#N/A) -> #N/A
A33: 32 | B33: =SMALL(dados!A$23:A$422,A33) -> 0.077291017 | C33: =VLOOKUP(B33,dados!A$23:E$422,4,0) -> 1 | D33: =VLOOKUP(B33,dados!A$23:E$422,5,0) -> 7 | E33: =COUNTIF(C$2:C33,1) -> 23 | F33: =COUNTIF(C$2:C33,2) -> 5 | G33: =COUNTIF(C$2:C33,3) -> 4 | L33: 30 | M33: 14.41875 | N33: 13.31875 | O33: 13.687042 | P33: 14.207208 | AG33: 1 | AH33: =IF(OR(M33<S$3,M33>S$7),M33,#N/A) -> #N/A | AI33: =AG33+1 -> 2 | AJ33: =IF(OR(N33<T$3,N33>T$7),N33,#N/A) -> #N/A | AK33: =AI33+1 -> 3 | AL33: =IF(OR(O33<U$3,O33>U$7),O33,#N/A) -> #N/A | AM33: =AK33+1 -> 4 | AN33: =IF(OR(P33<V$3,P33>V$7),P33,#N/A) -> #N/A
A34: 33 | B34: =SMALL(dados!A$23:A$422,A34) -> 0.078838512 | C34: =VLOOKUP(B34,dados!A$23:E$422,4,0) -> 2 | D34: =VLOOKUP(B34,dados!A$23:E$422,5,0) -> 22 | E34: =COUNTIF(C$2:C34,1) -> 23 | F34: =COUNTIF(C$2:C34,2) -> 6 | G34: =COUNTIF(C$2:C34,3) -> 4 | L34: 31 | M34: 14.58375 | N34: 14.716875 | O34: 14.314653 | P34: 13.867583 | AG34: 1 | AH34: =IF(OR(M34<S$3,M34>S$7),M34,#N/A) -> #N/A | AI34: =AG34+1 -> 2 | AJ34: =IF(OR(N34<T$3,N34>T$7),N34,#N/A) -> #N/A | AK34: =AI34+1 -> 3 | AL34: =IF(OR(O34<U$3,O34>U$7),O34,#N/A) -> #N/A | AM34: =AK34+1 -> 4 | AN34: =IF(OR(P34<V$3,P34>V$7),P34,#N/A) -> #N/A
A35: 34 | B35: =SMALL(dados!A$23:A$422,A35) -> 0.079938653 | C35: =VLOOKUP(B35,dados!A$23:E$422,4,0) -> 2 | D35: =VLOOKUP(B35,dados!A$23:E$422,5,0) -> 26 | E35: =COUNTIF(C$2:C35,1) -> 23 | F35: =COUNTIF(C$2:C35,2) -> 7 | G35: =COUNTIF(C$2:C35,3) -> 4 | L35: 32 | M35: 14.16875 | N35: 13.239375 | O35: 14.013972 | P35: 14.514313 | AG35: 1 | AH35: =IF(OR(M35<S$3,M35>S$7),M35,#N/A) -> #N/A | AI35: =AG35+1 -> 2 | AJ35: =IF(OR(N35<T$3,N35>T$7),N35,#N/A) -> #N/A | AK35: =AI35+1 -> 3 | AL35: =IF(OR(O35<U$3,O35>U$7),O35,#N/A) -> #N/A | AM35: =AK35+1 -> 4 | AN35: =IF(OR(P35<V$3,P35>V$7),P35,#N/A) -> #N/A
A36: 35 | B36: =SMALL(dados!A$23:A$422,A36) -> 0.08095821 | C36: =VLOOKUP(B36,dados!A$23:E$422,4,0) -> 2 | D36: =VLOOKUP(B36,dados!A$23:E$422,5,0) -> 26 | E36: =COUNTIF(C$2:C36,1) -> 23 | F36: =COUNTIF(C$2:C36,2) -> 8 | G36: =COUNTIF(C$2:C36,3) -> 4 | L36: 33 | M36: 13.9825 | N36: 14.525625 | O36: 13.827625 | P36: 14.231458 | AG36: 1 | AH36: =IF(OR(M36<S$3,M36>S$7),M36,#N/A) -> #N/A | AI36: =AG36+1 -> 2 | AJ36: =IF(OR(N36<T$3,N36>T$7),N36,#N/A) -> #N/A | AK36: =AI36+1 -> 3 | AL36: =IF(OR(O36<U$3,O36>U$7),O36,#N/A) -> #N/A | AM36: =AK36+1 -> 4 | AN36: =IF(OR(P36<V$3,P36>V$7),P36,#N/A) -> #N/A
... A401: 400 | B401: =SMALL(dados!A$23:A$422,A401) -> 0.99976439 | C401: =VLOOKUP(B401,dados!A$23:E$422,4,0) -> 1 | D401: =VLOOKUP(B401,dados!A$23:E$422,5,0) -> 9 | E401: =COUNTIF(C$2:C401,1) -> 287 | F401: =COUNTIF(C$2:C401,2) -> 71 | G401: =COUNTIF(C$2:C401,3) -> 42 | L401: 398 | M401: 14.2925 | N401: 14.070625 | O401: 13.844639 | P401: 13.60825 | AG401: 1 | AH401: =IF(OR(M401<S$3,M401>S$7),M401,#N/A) -> #N/A | AI401: =AG401+1 -> 2 | AJ401: =IF(OR(N401<T$3,N401>T$7),N401,#N/A) -> #N/A | AK401: =AI401+1 -> 3 | AL401: =IF(OR(O401<U$3,O401>U$7),O401,#N/A) -> #N/A | AM401: =AK401+1 -> 4 | AN401: =IF(OR(P401<V$3,P401>V$7),P401,#N/A) -> #N/A
